Workbook

Sheet How to Use
B2: WORKLOAD AND STORAGE CALCULATOR — HOW TO USE
B3: Azure Local / Storage Spaces Direct — Capacity Planning Tool
B5: This workbook helps you plan storage for an Azure Local cluster using Storage Spaces Direct (S2D). Enter your hardware specs and planned workloads — the calculator tells you how much usable storage you get and whether everything fits. You do NOT need to be a storage expert.
B7: QUICK START — 3 STEPS
C8: STEP 1 | D8: Go to 'Hardware Inputs'. Use the DROPDOWN MENUS to enter: node count, drive type, drives per node, and drive size. The calculator IMMEDIATELY shows your available storage in a big green number.
C9: STEP 2 | D9: Go to 'Workload Planner'. Choose your scenarios: AKS, Infrastructure VMs, Dev/Test, Backup, or Custom. For AVD, go to the 'AVD Planning' tab — all AVD inputs live there. Running counter shows remaining capacity.
C10: STEP 3 | D10: Review 'Capacity Report' and 'Volume Detail'. Print or share these with your team or customer. The report explains all the numbers and includes key concepts if anyone asks questions.
B12: COLOR GUIDE
C13: Blue on Yellow | D13: YOUR INPUT — only cells you edit. All have dropdowns or accept numbers.
C14: Green | D14: GOOD NEWS — available capacity, passing checks. Bigger green number = better.
C15: Blue on Light Blue | D15: CALCULATED — auto-calculated values. Do not edit.
C16: Red / Pink | D16: WARNING — footprint numbers, overcommit alerts, capacity exceeded.
C17: Orange | D17: CAUTION — reserve capacity, infrastructure overhead.
C18: Gray | D18: LABELS — descriptions explaining what each row means.
B20: TABS IN THIS WORKBOOK
C21: 1. Hardware Inputs | D21: WHERE YOU START. Enter cluster hardware with dropdowns. See your available capacity instantly. Shows TB vs TiB conversion for Windows Admin Center. Includes N+1 compute reminder.
C22: 2. Workload Planner | D22: WHERE YOU PLAN VOLUMES. Scenario-based: AVD summary (linked from AVD Planning), AKS (clusters + worker nodes + PVs + data services), Infrastructure VMs, Dev/Test, Backup/Archive, Custom. Enable/disable each scenario. Running capacity counter. Compute summary tracks vCPU AND RAM demand per scenario with N+1 failover checks. Overcommit sensitivity table covers all scenarios.
C23: 3. AVD Planning | D23: SINGLE SOURCE FOR ALL AVD. Enter ALL session host, profile, and compute settings here. Density matrix, host pool scale-out, FSLogix profile estimator, network bandwidth, gold image sizing, readiness checklist. All downstream tabs pull from this tab.
C24: 4. SOFS Planner | D24: SEPARATE SOFS CLUSTER SIZING. Hardware inputs, S2D pool calculation, FSLogix demand linked from Workload Planner (which pulls from AVD Planning), IOPS estimates, SOFS VM compute demand, readiness checklist. Use when profile storage is on a dedicated file server cluster.
C25: 5. Volume Detail | D25: PER-VOLUME TABLE. Name, resiliency, efficiency, logical size, footprint, usable capacity. PASS/FAIL check. Includes SOFS VM volumes.
C26: 6. Capacity Report | D26: WHAT YOU SHARE. Executive summary, capacity term glossary, reserve explanation, drive sizing advisory, N+1 compute reminder. Print this for project documentation.
C27: 7. Compute Report | D27: COMPUTE ANALYSIS. CPU and RAM capacity vs demand by scenario (including SOFS VMs). N+1 failover analysis, session host sizing, vCPU overcommit sensitivity table. All formula-linked to Hardware Inputs and Workload Planner.
C28: 8. Final Report | D28: ONE-PAGE SUMMARY. Hardware config, capacity allocation, scenario breakdown, volume creation table (TB + TiB), PowerShell commands, drive layout insight, compute analysis, best practice checks. All formula-linked — prints or shares as a snapshot.
C29: 9. Drive Layout Comparison | D29: WHAT-IF TOOL. Same total raw capacity, different drive counts per node. Shows how using more, smaller drives reduces reserve and increases available capacity. All formulas linked to Hardware Inputs — updates automatically.
C30: 10. Thin Provisioning | D30: READ IF CONSIDERING THIN. Risks, when acceptable, monitoring commands, best practices checklist.
C31: 11. References | D31: DOCUMENTATION LINKS. Microsoft Learn pages covering S2D, Azure Local, compute sizing, AVD, AKS, SOFS, and FSLogix topics.
C32: 12. Advanced Settings | D32: ADMIN ONLY. Capacity efficiency factor, infrastructure volume size, TB-to-TiB reference table. Override section for Workload Planner and SOFS Planner calculated fields. Also contains the CELL PROTECTION OVERRIDE switch.
B33: COMMON QUESTIONS
C34: Why does Windows show different numbers? | D34: Calculator uses TB (decimal). Windows uses TiB (binary). 1 TB = 0.909 TiB. Both are correct. Row 26 on Hardware Inputs shows TiB equivalent.
C35: Why is so much capacity 'lost'? | D35: Three-way mirror = 3 copies = 33% efficiency. This is WHY data survives 2 failures. Two-way = 50%. Dual Parity = 50-80% at 4+ nodes.
C36: Why can't I use all my pool? | D36: Three deductions: Drive overhead (~8%), Reserve (~1 drive/node for auto-repair), Infrastructure volume (~250 GB for Azure Local system).
C37: What if workloads don't fit? | D37: Options: fewer VMs, Two-Way instead of Three-Way where OK, more/smaller drives (see Drive Layout Comparison tab), more nodes, Dual Parity for archives.
C38: Should I use thin provisioning? | D38: Production: NO, use Fixed. Thin risks pool exhaustion = VMs crash. OK for dev/test and FSLogix with monitoring. See Thin Provisioning tab.
C39: NVMe+SSD vs All-NVMe? | D39: NVMe+SSD: NVMe becomes CACHE (not capacity). Only SSD counts. All-NVMe: all drives are capacity. Most common for new Azure Local deployments.
C40: Can I add drives/nodes later? | D40: Yes. New drives auto-join pool. Adding 3rd node unlocks three-way mirror. But sizing correctly upfront is simpler than expanding later.
C41: What does N+1 compute mean? | D41: Size VMs to fit on N-1 nodes. If 1 node goes down, all VMs must failover to remaining nodes. This is CPU/RAM, separate from storage.
B43: TIPS
B44: 1. | C44: Start with Hardware Inputs before planning workloads. Know what you have before planning what to put on it.
B45: 2. | C45: Use dropdown menus — don't type resiliency types manually. Typos break formulas.
B46: 3. | C46: Include ALL disks when estimating VM sizes (OS + data disks). Typical Windows Server = 80 GB OS + 100 GB data = 180 GB.
...

Sheet Hardware Inputs
B2: WORKLOAD AND STORAGE CALCULATOR — Azure Local
B3: Cluster Hardware Configuration
B5: INSTRUCTIONS: Enter values in BLUE cells (dropdowns provided). Everything else auto-calculates.
B7: STEP 1: ENTER YOUR CLUSTER HARDWARE
B8: Number of Cluster Nodes (Servers) | C8: 3 | D8: Select 1-16 | E8: Physical servers in the Azure Local cluster.
B9: Drive Media Configuration | C9: All-NVMe (No Cache) | D9: Select type | E9: All-NVMe: all drives are capacity. NVMe+SSD: NVMe is CACHE only.
B10: Capacity Drives per Node | C10: 4 | D10: Minimum: 2 | E10: Drives per node used for CAPACITY. Min 4 drives or more recommended
B11: Size of Each Capacity Drive (TB) | C11: 3.84 | D11: e.g. 1.6, 3.2, 7.68 | E11: Vendor-advertised drive size in TB.
B12: Cache Drives per Node (NVMe+SSD only) | C12: 0 | D12: Only if NVMe+SSD | E12: NVMe cache drives per node. These do NOT add capacity.
B13: Default Volume Provisioning | C13: Fixed (Thick) | D13: Select type | E13: RECOMMENDED: Fixed. See Thin Provisioning tab for risks.
B15: STEP 2: YOUR AVAILABLE STORAGE (Auto-Calculated)
B16: Total Capacity Drives | C16: =C8*C10 -> 12 | D16: drives | E16: Nodes x Capacity Drives (excludes cache)
B17: Cache Drives (if applicable) | C17: =IF(C9="NVMe + SSD (NVMe is Cache)",C8*C12,0) -> 0 | D17: drives | E17: Cache drives do NOT count toward capacity.
B18: Total Raw Capacity (Advertised) | C18: =C16*C11 -> 46.08 | D18: TB | E18: Capacity Drives x Drive Size.
B19: Usable Capacity per Drive | C19: =C11*'Advanced Settings'!C8 -> 3.5328 | D19: TB | E19: After NVMe overhead (~8%). See Advanced Settings tab.
B20: Total Usable Pool (Before Reserve) | C20: =C16*C19 -> 42.3936 | D20: TB | E20: All capacity drives pooled after overhead.
B21: Reserve (drive failure repair) | C21: =MIN(C8,4)*C19 -> 10.5984 | D21: TB | E21: 1 drive per node (max 4) for auto-repair.
B22: Infrastructure Volume (Azure Local) | C22: ='Advanced Settings'!C14 -> 0.75 | D22: TB footprint | E22: System volume created during deployment (~250 GB).
B24: YOUR AVAILABLE CAPACITY FOR VOLUMES | C24: =C20-C21-C22 -> 31.0452 | D24: TB | E24: Pool minus reserve minus infra = what you can use.
B26: What Windows Admin Center shows (TiB): | C26: =ROUND(C24*1000/1024,2) -> 30.32 | D26: TiB (approx) | E26: Windows uses TiB (binary). 1 TB = ~0.909 TiB. Numbers WILL differ.
B28: STEP 3: CLUSTER COMPUTE HARDWARE
B29: Physical CPU Cores per Node | C29: 32 | D29: cores | E29: Physical cores per server (check CPU spec).
B30: Hyperthreading (SMT) Enabled? | C30: Yes | D30: Yes/No | E30: If Yes, logical cores = physical × 2.
B31: RAM per Node (GB) | C31: 256 | D31: GB | E31: Total physical RAM per node.
B32: Host OS / Management Reserved RAM (GB) | C32: 32 | D32: GB | E32: Reserved for Hyper-V host OS, agents, S2D. Typical: 16-32 GB.
B34: COMPUTE CAPACITY (Auto-Calculated)
B35: Logical vCPU per Node | C35: =IF(C30="Yes",C29*2,C29) -> 64 | D35: vCPU | E35: Logical cores available per node for VMs.
B36: Usable RAM per Node (GB) | C36: =C31-C32 -> 224 | D36: GB | E36: RAM minus host OS reservation.
B37: Total Cluster vCPU (all nodes) | C37: =C35*C8 -> 192 | D37: vCPU | E37: All nodes combined.
B38: Total Cluster Usable RAM (all nodes) | C38: =C36*C8 -> 672 | D38: GB | E38: All usable RAM across cluster.
B39: N+1 Available vCPU (1 node down) | C39: =C35*(C8-1) -> 128 | D39: vCPU | E39: With 1 node down for maintenance/failover.
B40: N+1 Available RAM (1 node down) | C40: =C36*(C8-1) -> 448 | D40: GB | E40: RAM capacity with 1 node down.
B42: RESILIENCY REFERENCE
B43: Type | C43: Efficiency | D43: Min Nodes | E43: Fault Tolerance
B44: Two-Way Mirror | C44: 50.0% | D44: 2 | E44: 1 failure
B45: Three-Way Mirror | C45: 33.3% | D45: 3 | E45: 2 failures
B46: Dual Parity (4-6) | C46: 50.0% | D46: 4 | E46: 2 failures
B47: Dual Parity (7-8) | C47: 66.7% | D47: 7 | E47: 2 failures
B48: Dual Parity (9-15 flash) | C48: 75.0% | D48: 9 | E48: 2 failures
B49: Dual Parity (16 flash) | C49: 80.0% | D49: 16 | E49: 2 failures
...

Sheet Workload Planner
B2: SCENARIO-BASED WORKLOAD PLANNER
B3: Plan storage by workload type — AVD, AKS, Infrastructure, Dev/Test, and more
B5: AVAILABLE POOL CAPACITY: | C5: ='Hardware Inputs'!C24 -> 31.0452 | D5: TB | E5: ='Hardware Inputs'!C24 -> 31.0452
B7: SCENARIO 1: AVD DEPLOYMENT
B8: Enable AVD scenario? | C8: ='AVD Planning'!C6 -> No | F8: Linked from AVD Planning tab.
B9: ➡ All AVD inputs have moved to the AVD Planning tab. | F9: Click AVD Planning tab for all session host, profile, and compute inputs.
B10: Number of AVD session host VMs | C10: ='AVD Planning'!C9 -> 32 | D10: VMs
B11: OS disk per host (GB) | C11: ='AVD Planning'!C10 -> 127 | D11: GB
B12: Data/temp disk per host (GB) | C12: ='AVD Planning'!C11 -> 50 | D12: GB
B13: Host resiliency type | C13: ='AVD Planning'!C12 -> Two-Way Mirror | D13: ='AVD Planning'!D12 -> 50% eff.
B14: Session host volume (logical) | C14: ='AVD Planning'!C13 -> 0 | D14: TB
B15: Session host footprint in pool | C15: ='AVD Planning'!C14 -> 0 | D15: TB
B16: FSLogix Profiles — Summary
B17: Profile storage location | C17: ='AVD Planning'!C17 -> S2D Volume (local)
B18: Total AVD users | C18: ='AVD Planning'!C18 -> 1300 | D18: users
B19: Concurrent users | C19: ='AVD Planning'!C19 -> 300 | D19: users
B20: Profile size per user (GB) | C20: ='AVD Planning'!C20 -> 5 | D20: GB
B21: Growth buffer | C21: ='AVD Planning'!C21 -> 0.3 | D21: overhead
B22: Profile resiliency type | C22: ='AVD Planning'!C22 -> Three-Way Mirror | D22: ='AVD Planning'!D22 -> 33% eff.
B23: Profile volume (logical) | C23: ='AVD Planning'!C23 -> 0 | D23: TB
B24: Profile footprint in pool | C24: ='AVD Planning'!C24 -> 0 | D24: TB
B25: AVD TOTAL FOOTPRINT | C25: ='AVD Planning'!C25 -> 0 | D25: TB
B26: AVD Compute Summary
B27: vCPU per session host | C27: ='AVD Planning'!C28 -> 8 | D27: vCPU
B28: RAM per session host (GB) | C28: ='AVD Planning'!C29 -> 32 | D28: GB
B29: vCPU overcommit ratio | C29: ='AVD Planning'!C30 -> 4:1 | D29: ratio
B30: vCPU per user | C30: ='AVD Planning'!C31 -> 2 | D30: vCPU
B31: RAM per user (GB) | C31: ='AVD Planning'!C32 -> 4 | D31: GB
B32: Users per session host (max) | C32: ='AVD Planning'!C33 -> 0 | D32: users/host
B33: Session hosts needed | C33: ='AVD Planning'!C34 -> 0 | D33: VMs
B34: Session host VM check | C34: ='AVD Planning'!C35
B35: Total AVD vCPU demand | C35: ='AVD Planning'!C36 -> 0 | D35: vCPU
B36: Total AVD RAM demand (GB) | C36: ='AVD Planning'!C37 -> 0 | D36: GB
B37: Effective vCPU (with overcommit) | C37: ='AVD Planning'!C38 -> 0 | D37: vCPU
B43: SCENARIO 2: AKS ON AZURE LOCAL
B44: Enable AKS scenario? | C44: No | F44: Set to No to skip this scenario.
B45: AKS Cluster VMs
B46: Number of AKS clusters | C46: 1 | D46: clusters | F46: AKS Arc clusters on this Azure Local instance.
B47: Control plane nodes (total across clusters) | C47: 1 | D47: nodes | F47: Typically 1 or 3 per cluster (HA = 3).
B48: Worker nodes (total across clusters) | C48: 3 | D48: nodes | F48: All worker nodes across all node pools.
...

Sheet AVD Planning
B2: AVD PLANNING — SINGLE SOURCE FOR ALL AVD CONFIGURATION
B3: All AVD inputs are entered here. Workload Planner, Compute Report, Final Report, Volume Detail, and SOFS Planner all pull from this tab.
B5: SECTION 1: AVD SCENARIO INPUTS
B6: Enable AVD scenario? | C6: No | F6: Set to No to skip AVD entirely. All downstream tabs respect this flag.
B8: Session Hosts — Storage
B9: Number of AVD session host VMs | C9: 32 | D9: VMs | F9: Total session host VMs across all host pools.
B10: OS disk per host (GB) | C10: 127 | D10: GB | F10: Typical: 127 GB (Windows 11 multi-session).
B11: Data/temp disk per host (GB) | C11: 50 | D11: GB | F11: Additional data disks. Set to 0 if none.
B12: Host resiliency type | C12: Two-Way Mirror | D12: =CONCATENATE(TEXT(IF(C12="Three-Way Mirror",1/3,IF(C12="Two-Way Mirror",0.5,IF(C12="Dual Parity",IF('Hardware Inputs'!C8>=16,0.8,IF('Hardware Inputs'!C8>=9,0.75,IF('Hardware Inputs'!C8>=7,2/3,0.5))),IF(C12="Nested Two-Way Mirror",0.25,1/3)))),"0%")," eff.") -> 50% eff. | F12: =IF(C12=IF('Hardware Inputs'!C8>=3,"Three-Way Mirror","Two-Way Mirror"),"","Note: "&'Hardware Inputs'!C8&"-node cluster default = "&IF('Hardware Inputs'!C8>=3,"Three-Way Mirror","Two-Way Mirror")) -> Note: 3-node cluster default = Three-Way Mirror
B13: Session host volume (logical) | C13: =IF($C$6="No",0,IF(C9=0,0,ROUND(C9*(C10+C11)/1024,2))) -> 0 | D13: TB | F13: =IF(C13>64,"WARNING: Exceeds 64 TB max volume size!","")
B14: Session host footprint in pool | C14: =IF(C13=0,0,ROUND(C13/IF(C12="Three-Way Mirror",1/3,IF(C12="Two-Way Mirror",0.5,IF(C12="Dual Parity",IF('Hardware Inputs'!C8>=16,0.8,IF('Hardware Inputs'!C8>=9,0.75,IF('Hardware Inputs'!C8>=7,2/3,0.5))),IF(C12="Nested Two-Way Mirror",0.25,1/3)))),2)) -> 0 | D14: TB | F14: Logical / efficiency = pool space consumed.
B16: FSLogix Profiles — Storage
B17: Profile storage location | C17: S2D Volume (local) | F17: S2D = local cluster volume. SOFS = dedicated file server (see SOFS Planner). External/Azure = 0 pool footprint.
B18: Total AVD users | C18: 1300 | D18: users | F18: All users who have a profile container.
B19: Concurrent (connected) users | C19: 300 | D19: users | F19: Peak concurrent sessions.
B20: Profile container size per user (GB) | C20: 5 | D20: GB | F20: Start at 5 GB if unknown. Measure after 30 days. See Section 3 estimator below.
B21: Growth buffer (%) | C21: 0.3 | D21: overhead | F21: Buffer for growth. 20-50% recommended.
B22: Profile resiliency type | C22: Three-Way Mirror | D22: =IF(C17<>"S2D Volume (local)","n/a",CONCATENATE(TEXT(IF(C22="Three-Way Mirror",1/3,IF(C22="Two-Way Mirror",0.5,IF(C22="Dual Parity",IF('Hardware Inputs'!C8>=16,0.8,IF('Hardware Inputs'!C8>=9,0.75,IF('Hardware Inputs'!C8>=7,2/3,0.5))),IF(C22="Nested Two-Way Mirror",0.25,1/3)))),"0%")," eff.")) -> 33% eff.
B23: Profile volume (logical) | C23: =IF($C$6="No",0,IF(C18=0,0,ROUND((C18*C20*(1+C21))/1024,2))) -> 0 | D23: TB | F23: =IF(C23>64,"WARNING: Exceeds 64 TB max volume size!","")
B24: Profile footprint in pool | C24: =IF(OR($C$6="No",C17<>"S2D Volume (local)"),0,IF(C23=0,0,ROUND(C23/IF(C22="Three-Way Mirror",1/3,IF(C22="Two-Way Mirror",0.5,IF(C22="Dual Parity",IF('Hardware Inputs'!C8>=16,0.8,IF('Hardware Inputs'!C8>=9,0.75,IF('Hardware Inputs'!C8>=7,2/3,0.5))),IF(C22="Nested Two-Way Mirror",0.25,1/3)))),2))) -> 0 | D24: TB | F24: If profiles on external/cloud storage, footprint = 0 in pool.
B25: AVD TOTAL STORAGE FOOTPRINT | C25: =C14+C24 -> 0 | D25: TB
B27: AVD Compute Planning
B28: vCPU per session host VM | C28: 8 | D28: vCPU | F28: Typical: 4-8 vCPU per session host. Size per VM SKU.
B29: RAM per session host VM (GB) | C29: 32 | D29: GB | F29: Typical: 16-32 GB per session host VM.
B30: vCPU overcommit ratio | C30: 4:1 | D30: ratio | F30: vCPU overcommit. 1:1 = no overcommit. 4:1 = 4 vCPU share 1 physical core. Hyper-V supports vCPU overcommit; memory cannot be overcommitted.
B31: vCPU per user | C31: 2 | D31: vCPU | F31: Allocation per concurrent user. Light=1, Medium=2, Power=4.
B32: RAM per user (GB) | C32: 4 | D32: GB | F32: Physical RAM per user. Light=2, Medium=4, Power=8 GB.
B33: Users per session host (max) | C33: =IF($C$6="No",0,MIN(INT(C28/C31),INT(C29/C32))) -> 0 | D33: users/host | F33: Min of vCPU and RAM constraints per host.
B34: Session hosts needed (for concurrent users) | C34: =IF($C$6="No",0,IF(C33=0,0,ROUNDUP(C19/C33,0))) -> 0 | D34: VMs | F34: Concurrent users ÷ users per host (rounded up).
B35: Session host VM check | C35: =IF($C$6="No","",IF(C9>=C34,"✓ PASS — "&C9&" VMs ≥ "&C34&" needed","✗ FAIL — Need "&C34&" VMs but only "&C9&" configured"))
B36: Total AVD vCPU demand | C36: =IF($C$6="No",0,C9*C28) -> 0 | D36: vCPU | F36: Session host VMs × vCPU per host.
B37: Total AVD RAM demand (GB) | C37: =IF($C$6="No",0,C9*C29) -> 0 | D37: GB | F37: Total physical RAM needed. Hyper-V reserves full RAM per VM (no overcommit).
B38: Effective vCPU (with overcommit) | C38: =IF($C$6="No",0,ROUND(C36/IF(C30="1:1",1,IF(C30="2:1",2,IF(C30="3:1",3,IF(C30="4:1",4,1)))),0)) -> 0 | D38: vCPU | F38: Physical cores needed after vCPU overcommit ratio applied.
B40: AVD Compute Fit Check
B41: vCPU fit (all nodes, with overcommit) | C41: =IF($C$6="No","",IF(C38<='Hardware Inputs'!C37,"✓ PASS — "&C38&" of "&'Hardware Inputs'!C37&" vCPU ("&ROUND(C38/'Hardware Inputs'!C37*100,0)&"%)","✗ FAIL — Need "&C38&" but only "&'Hardware Inputs'!C37&" available")) | F41: AVD effective vCPU (after overcommit) vs total cluster vCPU.
B42: RAM fit (all nodes) | C42: =IF($C$6="No","",IF(C37<='Hardware Inputs'!C38,"✓ PASS — "&C37&" of "&'Hardware Inputs'!C38&" GB ("&ROUND(C37/'Hardware Inputs'!C38*100,0)&"%)","✗ FAIL — Need "&C37&" GB but only "&'Hardware Inputs'!C38&" GB available")) | F42: AVD total RAM vs cluster RAM. Full reservation required (no overcommit).
B43: N+1 vCPU fit (with overcommit) | C43: =IF($C$6="No","",IF(C38<='Hardware Inputs'!C39,"✓ PASS — "&C38&" of "&'Hardware Inputs'!C39&" vCPU ("&ROUND(C38/'Hardware Inputs'!C39*100,0)&"%)","⚠ WARNING — Need "&C38&" but N+1 only has "&'Hardware Inputs'!C39&" vCPU")) | F43: Effective vCPU with 1 node down (patching/failover).
B44: N+1 RAM fit (1 node down) | C44: =IF($C$6="No","",IF(C37<='Hardware Inputs'!C40,"✓ PASS — "&C37&" of "&'Hardware Inputs'!C40&" GB ("&ROUND(C37/'Hardware Inputs'!C40*100,0)&"%)","⚠ WARNING — Need "&C37&" GB but N+1 only has "&'Hardware Inputs'!C40&" GB")) | F44: RAM with 1 node down. Full reservation (no overcommit).
B46: SECTION 2: SESSION HOST DENSITY MATRIX
B47: Shows maximum users per host at different vCPU/user ratios, using your inputs above.
...

Sheet SOFS Planner
B2: SOFS Planner — Separate File Server Cluster for FSLogix Profiles
B3: Sizes a dedicated SOFS cluster (separate from compute cluster) for hosting FSLogix profile containers via CA SMB shares backed by S2D.
B5: SECTION 1: SOFS SCENARIO INPUTS
B6: Enable SOFS scenario? | C6: No | F6: Set to No to skip SOFS entirely. All downstream tabs respect this flag.
B8: SOFS CLUSTER HARDWARE
B9: SOFS node count | C9: 3 | D9: nodes | F9: Minimum 2 nodes for SOFS + cloud witness. Microsoft supported production model.
B10: Drives per SOFS node | C10: 4 | D10: drives | F10: NVMe or SSD recommended for FSLogix IOPS. Same count per node required.
B11: Drive capacity (each) | C11: =IF($C$6="No",0,IF(C30=0,0,ROUNDUP(C30/(C9*C10*C19*C14-1),2))) -> 0 | D11: TB | F11: Auto-calculated from profile demand. Drive size = pool needed ÷ (nodes × drives × resiliency eff × cap eff - 1 drive reserve).
B12: SOFS STORAGE POOL
B13: Resiliency type | C13: =IF($C$6="No","",'AVD Planning'!C22) | F13: Linked from AVD Planning C22. Change profile resiliency there.
B14: Capacity efficiency factor | C14: 0.92 | F14: S2D filesystem overhead. Default 92% (same as compute cluster).
B15: Profile container type | C15: Single | F15: Single = 1 VHD per user (profile+Office combined). Split = 3 VHDs per user (profile + Office/ODFC + other). Split triples IOPS and volume count.
B16: SOFS volume resiliency on main cluster | C16: Two-Way Mirror | F16: Resiliency for the SOFS VM storage volumes on the Azure Local compute cluster. Independent from SOFS internal resiliency.
B18: Total raw capacity | C18: =IF($C$6="No",0,C9*C10*C11) -> 0 | D18: TB | F18: Nodes × drives/node × drive size.
B19: Resiliency efficiency | C19: =IF($C$6="No",0,IF(C13="Three-Way Mirror",1/3,IF(C13="Two-Way Mirror",0.5,IF(C13="Dual Parity",IF(C9>=16,0.8,IF(C9>=9,0.75,IF(C9>=7,2/3,0.5))),IF(C13="Nested Two-Way Mirror",0.25,1/3))))) -> 0 | F19: Data fraction after mirror/parity overhead.
B20: Usable capacity (after resiliency + overhead) | C20: =IF($C$6="No",0,ROUND(C18*C19*C14,2)) -> 0 | D20: TB | F20: Raw × resiliency efficiency × capacity efficiency factor.
B21: Drive reserve (largest drive capacity) | C21: =IF($C$6="No",0,C11) -> 0 | D21: TB | F21: S2D reserves capacity of largest drive for rebuild. Deducted from raw.
B22: Available for volumes | C22: =IF($C$6="No",0,MAX(0,ROUND(C20-C21,2))) -> 0 | D22: TB | F22: Usable minus drive reserve. This is what you can allocate to FSLogix volumes.
B24: FSLOGIX PROFILE DEMAND
B25: Profile storage location (from WP) | C25: =IF($C$6="No","",'Workload Planner'!C17) | F25: Linked from Workload Planner C17. SOFS tab relevant when NOT "S2D Volume (local)".
B26: Total AVD users | C26: =IF($C$6="No",0,'Workload Planner'!C18) -> 0 | D26: users | F26: Linked from Workload Planner.
B27: Profile size per user | C27: =IF($C$6="No",0,'Workload Planner'!C20) -> 0 | D27: GB
B28: Growth buffer | C28: =IF($C$6="No",0,'Workload Planner'!C21) -> 0
B29: Profile logical demand | C29: =IF($C$6="No",0,ROUND((C26*C27*(1+C28))/1024,2)) -> 0 | D29: TB | F29: Users × profile size × (1 + growth buffer) / 1024.
B30: Profile footprint on SOFS (after resiliency) | C30: =IF($C$6="No",0,IF(C19=0,0,ROUND(C29/C19,2))) -> 0 | D30: TB | F30: Logical demand ÷ resiliency efficiency. This is the actual pool space consumed.
B31: Remaining SOFS capacity after profiles | C31: =IF($C$6="No",0,ROUND(C22-C30,2)) -> 0 | D31: TB | F31: Available minus footprint. Negative = need more drives/nodes.
B32: Capacity utilization | C32: =IF($C$6="No",0,IF(C22=0,0,C30/C22)) -> 0 | F32: Keep under 80% for S2D performance headroom.
B34: IOPS ESTIMATE
B35: Steady-state IOPS per user | C35: 10 | D35: IOPS | F35: Typical FSLogix steady state: ~10 IOPS per active session.
B36: Login/logoff storm IOPS per user | C36: 50 | D36: IOPS | F36: Peak during login/logoff: ~50 IOPS per user (VHD mount/dismount).
B37: Concurrent users | C37: =IF($C$6="No",0,'Workload Planner'!C19) -> 0 | D37: users
B38: Login storm % (simultaneous logins) | C38: 0.2 | F38: % of users logging in simultaneously during peak (e.g., 9 AM). 10-30% typical.
B39: Steady-state total IOPS | C39: =IF($C$6="No",0,C37*C35*IF(C15="Split",3,1)) -> 0 | D39: IOPS
B40: Peak storm IOPS | C40: =IF($C$6="No",0,ROUND(((C37*(1-C38)*C35)+(C37*C38*C36))*IF(C15="Split",3,1),0)) -> 0 | D40: IOPS | F40: Steady users × steady IOPS + storm users × storm IOPS. Plan storage to handle this.
B42: SOFS VM COMPUTE (on main cluster)
B43: vCPU per SOFS VM | C43: 8 | D43: vCPU | F43: Typical SOFS VM: 4-8 vCPU. Depends on concurrent SMB sessions.
B44: RAM per SOFS VM | C44: 16 | D44: GB | F44: Typical SOFS VM: 8-16 GB. More for large concurrent profile mounts.
B45: SOFS VM count | C45: =IF($C$6="No",0,C9) -> 0 | D45: VMs | F45: Equals SOFS node count. Each node = 1 VM on the Azure Local cluster.
B46: Total SOFS vCPU demand | C46: =IF($C$6="No",0,C45*C43) -> 0 | D46: vCPU | F46: Total vCPU consumed on main cluster by SOFS VMs.
B47: Total SOFS RAM demand | C47: =IF($C$6="No",0,C45*C44) -> 0 | D47: GB | F47: Total RAM consumed on main cluster by SOFS VMs.
...

Sheet Volume Detail
B2: VOLUME DETAIL — DEPLOYMENT REFERENCE
B3: Use this table when creating volumes in Windows Admin Center or PowerShell. Copy volume names and sizes directly.
B5: Volume Name | C5: Resiliency | D5: Create Size (TB) | E5: Create Size (TiB)* | F5: Pool Footprint (TB) | G5: Copies | H5: Efficiency | I5: Status
B6: AVD-SessionHosts | C6: ='Workload Planner'!C13 -> Two-Way Mirror | D6: ='Workload Planner'!C14 -> 0 | E6: =IF(D6=0,0,ROUND(D6*(1000/1024)^3,2)) -> 0 | F6: ='Workload Planner'!C15 -> 0 | G6: =IF(C6="Two-Way Mirror","2x",IF(C6="Three-Way Mirror","3x","parity")) -> 2x | H6: =IF(C6="Three-Way Mirror",1/3,IF(C6="Two-Way Mirror",0.5,IF(C6="Dual Parity",IF('Hardware Inputs'!C8>=16,0.8,IF('Hardware Inputs'!C8>=9,0.75,IF('Hardware Inputs'!C8>=7,2/3,0.5))),IF(C6="Nested Two-Way Mirror",0.25,1/3)))) -> 0.5 | I6: =IF(D6=0,"— Disabled",IF(D6>64,"FAIL: >64 TB","PASS")) -> — Disabled
B7: AVD-Profiles | C7: ='Workload Planner'!C22 -> Three-Way Mirror | D7: ='Workload Planner'!C23 -> 0 | E7: =IF(D7=0,0,ROUND(D7*(1000/1024)^3,2)) -> 0 | F7: ='Workload Planner'!C24 -> 0 | G7: =IF(C7="Two-Way Mirror","2x",IF(C7="Three-Way Mirror","3x","parity")) -> 3x | H7: =IF(C7="Three-Way Mirror",1/3,IF(C7="Two-Way Mirror",0.5,IF(C7="Dual Parity",IF('Hardware Inputs'!C8>=16,0.8,IF('Hardware Inputs'!C8>=9,0.75,IF('Hardware Inputs'!C8>=7,2/3,0.5))),IF(C7="Nested Two-Way Mirror",0.25,1/3)))) -> 0.33333333 | I7: =IF(D7=0,"— Disabled",IF(D7>64,"FAIL: >64 TB","PASS")) -> — Disabled
B8: AKS-Cluster | C8: ='Workload Planner'!C53 -> Three-Way Mirror | D8: ='Workload Planner'!C54 -> 0 | E8: =IF(D8=0,0,ROUND(D8*(1000/1024)^3,2)) -> 0 | F8: ='Workload Planner'!C55 -> 0 | G8: =IF(C8="Two-Way Mirror","2x",IF(C8="Three-Way Mirror","3x","parity")) -> 3x | H8: =IF(C8="Three-Way Mirror",1/3,IF(C8="Two-Way Mirror",0.5,IF(C8="Dual Parity",IF('Hardware Inputs'!C8>=16,0.8,IF('Hardware Inputs'!C8>=9,0.75,IF('Hardware Inputs'!C8>=7,2/3,0.5))),IF(C8="Nested Two-Way Mirror",0.25,1/3)))) -> 0.33333333 | I8: =IF(D8=0,"— Disabled",IF(D8>64,"FAIL: >64 TB","PASS")) -> — Disabled
B9: Infra-VMs | C9: ='Workload Planner'!C69 -> Three-Way Mirror | D9: ='Workload Planner'!C70 -> 0 | E9: =IF(D9=0,0,ROUND(D9*(1000/1024)^3,2)) -> 0 | F9: ='Workload Planner'!C71 -> 0 | G9: =IF(C9="Two-Way Mirror","2x",IF(C9="Three-Way Mirror","3x","parity")) -> 3x | H9: =IF(C9="Three-Way Mirror",1/3,IF(C9="Two-Way Mirror",0.5,IF(C9="Dual Parity",IF('Hardware Inputs'!C8>=16,0.8,IF('Hardware Inputs'!C8>=9,0.75,IF('Hardware Inputs'!C8>=7,2/3,0.5))),IF(C9="Nested Two-Way Mirror",0.25,1/3)))) -> 0.33333333 | I9: =IF(D9=0,"— Disabled",IF(D9>64,"FAIL: >64 TB","PASS")) -> — Disabled
B10: DevTest-VMs | C10: ='Workload Planner'!C86 -> Two-Way Mirror | D10: ='Workload Planner'!C87 -> 0 | E10: =IF(D10=0,0,ROUND(D10*(1000/1024)^3,2)) -> 0 | F10: ='Workload Planner'!C88 -> 0 | G10: =IF(C10="Two-Way Mirror","2x",IF(C10="Three-Way Mirror","3x","parity")) -> 2x | H10: =IF(C10="Three-Way Mirror",1/3,IF(C10="Two-Way Mirror",0.5,IF(C10="Dual Parity",IF('Hardware Inputs'!C8>=16,0.8,IF('Hardware Inputs'!C8>=9,0.75,IF('Hardware Inputs'!C8>=7,2/3,0.5))),IF(C10="Nested Two-Way Mirror",0.25,1/3)))) -> 0.5 | I10: =IF(D10=0,"— Disabled",IF(D10>64,"FAIL: >64 TB","PASS")) -> — Disabled
B11: Backup-Archive | C11: ='Workload Planner'!C101 -> Dual Parity | D11: ='Workload Planner'!C102 -> 0 | E11: =IF(D11=0,0,ROUND(D11*(1000/1024)^3,2)) -> 0 | F11: ='Workload Planner'!C103 -> 0 | G11: =IF(C11="Two-Way Mirror","2x",IF(C11="Three-Way Mirror","3x","parity")) -> parity | H11: =IF(C11="Three-Way Mirror",1/3,IF(C11="Two-Way Mirror",0.5,IF(C11="Dual Parity",IF('Hardware Inputs'!C8>=16,0.8,IF('Hardware Inputs'!C8>=9,0.75,IF('Hardware Inputs'!C8>=7,2/3,0.5))),IF(C11="Nested Two-Way Mirror",0.25,1/3)))) -> 0.5 | I11: =IF(D11=0,"— Disabled",IF(D11>64,"FAIL: >64 TB","PASS")) -> — Disabled
B12: Custom | C12: ='Workload Planner'!C108 -> Three-Way Mirror | D12: ='Workload Planner'!C109 -> 0 | E12: =IF(D12=0,0,ROUND(D12*(1000/1024)^3,2)) -> 0 | F12: ='Workload Planner'!C110 -> 0 | G12: =IF(C12="Two-Way Mirror","2x",IF(C12="Three-Way Mirror","3x","parity")) -> 3x | H12: =IF(C12="Three-Way Mirror",1/3,IF(C12="Two-Way Mirror",0.5,IF(C12="Dual Parity",IF('Hardware Inputs'!C8>=16,0.8,IF('Hardware Inputs'!C8>=9,0.75,IF('Hardware Inputs'!C8>=7,2/3,0.5))),IF(C12="Nested Two-Way Mirror",0.25,1/3)))) -> 0.33333333 | I12: =IF(D12=0,"— Disabled",IF(D12>64,"FAIL: >64 TB","PASS")) -> — Disabled
B13: =IF('SOFS Planner'!$C$6="No","","SOFS-Node1-Vol") | C13: ='SOFS Planner'!C16 -> Two-Way Mirror | D13: =IF('SOFS Planner'!$C$6="No",0,IF('SOFS Planner'!C9>=1,ROUND('SOFS Planner'!C30/'SOFS Planner'!C9,2),0)) -> 0 | E13: =IF(D13=0,0,ROUND(D13*(1000/1024)^3,2)) -> 0 | F13: =IF(D13=0,0,ROUND(D13/IF(C13="Three-Way Mirror",1/3,IF(C13="Two-Way Mirror",0.5,IF(C13="Dual Parity",IF('Hardware Inputs'!C8>=16,0.8,IF('Hardware Inputs'!C8>=9,0.75,IF('Hardware Inputs'!C8>=7,2/3,0.5))),IF(C13="Nested Two-Way Mirror",0.25,1/3)))),2)) -> 0 | G13: =IF(D13=0,"",IF(C13="Two-Way Mirror","2x",IF(C13="Three-Way Mirror","3x","parity"))) | I13: =IF(D13=0,"— Disabled",IF(D13>64,"FAIL: >64 TB","PASS")) -> — Disabled
B14: =IF('SOFS Planner'!$C$6="No","",IF('SOFS Planner'!C9>=2,"SOFS-Node2-Vol","")) | C14: =IF(B14<>"",C13,"") | D14: =IF(B14<>"",D13,0) -> 0 | E14: =IF(D14=0,0,ROUND(D14*(1000/1024)^3,2)) -> 0 | F14: =IF(D14=0,0,F13) -> 0 | G14: =IF(D14=0,"",G13) | I14: =IF(D14=0,"— Disabled",IF(D14>64,"FAIL: >64 TB","PASS")) -> — Disabled
B15: =IF('SOFS Planner'!$C$6="No","",IF('SOFS Planner'!C9>=3,"SOFS-Node3-Vol","")) | C15: =IF(B15<>"",C13,"") | D15: =IF(B15<>"",D13,0) -> 0 | E15: =IF(D15=0,0,ROUND(D15*(1000/1024)^3,2)) -> 0 | F15: =IF(D15=0,0,F13) -> 0 | G15: =IF(D15=0,"",G13) | I15: =IF(D15=0,"— Disabled",IF(D15>64,"FAIL: >64 TB","PASS")) -> — Disabled
B16: =IF('SOFS Planner'!$C$6="No","",IF('SOFS Planner'!C9>=4,"SOFS-Node4-Vol","")) | C16: =IF(B16<>"",C13,"") | D16: =IF(B16<>"",D13,0) -> 0 | E16: =IF(D16=0,0,ROUND(D16*(1000/1024)^3,2)) -> 0 | F16: =IF(D16=0,0,F13) -> 0 | G16: =IF(D16=0,"",G13) | I16: =IF(D16=0,"— Disabled",IF(D16>64,"FAIL: >64 TB","PASS")) -> — Disabled
B23: TOTALS | D23: =SUM(D6:D16) -> 0 | E23: =SUM(E6:E16) -> 0 | F23: =SUM(F6:F16) -> 0 | I23: =COUNTIF(I6:I16,"PASS")&" of "&COUNTIF(I6:I16,"<>"&"— Disabled")&" PASS" -> 0 of 0 PASS
B25: FIT CHECK
B26: =IF('Workload Planner'!C128<0,"FAIL: Exceeds pool by "&TEXT(ABS('Workload Planner'!C128),"0.00")&" TB. Remove workloads or add drives.",IF('Workload Planner'!C129>0.7,"WARNING: "&TEXT('Workload Planner'!C129,"0.0%")&" utilized. Above 70% = limited rebuild headroom.","PASS: "&TEXT('Workload Planner'!C129,"0.0%")&" utilized. Healthy headroom for drive failure repair.")) -> PASS: 0.0% utilized. Healthy headroom for drive failure repair.
B28: * TiB column: What Windows/PowerShell will report. This calculator uses TB (decimal) everywhere else. 1 TB = ~0.909 TiB. Both are correct — different units for the same bytes.
B29: ="Microsoft recommends volume count as a multiple of your node count ("&'Hardware Inputs'!C8&") for balanced data distribution. Consider splitting large Infrastructure or Dev/Test volumes across "&'Hardware Inputs'!C8&" equal volumes where practical. AVD profiles and AKS PVs typically require a single volume." -> Microsoft recommends volume count as a multiple of your node count (3) for balanced data distribution. Consider splitting large Infrastructure or Dev/Test volumes across 3 equal volumes where practical. AVD profiles and AKS PVs typically require a single volume.

Sheet Capacity Report
B2: S2D CAPACITY REPORT
B4: EXECUTIVE SUMMARY
B5: Cluster Nodes | C5: ='Hardware Inputs'!C8 -> 3 | D5: servers
B6: Drive Config | C6: ='Hardware Inputs'!C9 -> All-NVMe (No Cache)
B7: Capacity Drives | C7: ='Hardware Inputs'!C16 -> 12 | D7: drives
B8: Drive Size | C8: ='Hardware Inputs'!C11 -> 3.84 | D8: TB each
B9: Raw Capacity | C9: ='Hardware Inputs'!C18 -> 46.08 | D9: TB
B10: After Overhead | C10: ='Hardware Inputs'!C20 -> 42.3936 | D10: TB
B11: Pool Reserve | C11: ='Hardware Inputs'!C21 -> 10.5984 | D11: TB
B12: Infra Volume | C12: ='Hardware Inputs'!C22 -> 0.75 | D12: TB
B13: AVAILABLE POOL | C13: ='Hardware Inputs'!C24 -> 31.0452 | D13: TB
B14: WAC Display | C14: ='Hardware Inputs'!C26 -> 30.32 | D14: TiB
B15: Workload Footprint | C15: ='Workload Planner'!C124 -> 0 | D15: TB
B16: Usable Volume Capacity | C16: ='Workload Planner'!C125 -> 0 | D16: TB
B17: Remaining Free | C17: ='Workload Planner'!C128 -> 31.0452 | D17: TB
B18: Pool Utilization | C18: ='Workload Planner'!C129 -> 0
B20: CAPACITY TERMS
B21: Raw Capacity | C21: Drive label size. Manufacturer's decimal number.
B22: Usable Capacity | C22: After ~8% overhead (TB-to-TiB + NVMe reserves).
B23: Pool Capacity | C23: All usable capacity pooled. Excludes cache.
B24: Reserve | C24: 1 drive/node (max 4) for auto-repair.
B25: Infra Volume | C25: ~250 GB for Azure Local system metadata.
B26: Available Pool | C26: Pool - reserve - infra. What you allocate.
B27: Volume Size | C27: Logical size you request. What OS shows.
B28: Footprint | C28: Physical pool space. 1TB 3-way mirror = 3TB.
B29: Efficiency | C29: Usable/footprint. 2-way=50%, 3-way=33%.
B30: TB vs TiB | C30: Manufacturers=TB. Windows=TiB. 1TB=0.909TiB.
B32: WHY RESERVE IS CRITICAL
B33: Drive fails: | C33: S2D rebuilds lost data onto other drives. Needs FREE pool space.
B34: No reserve: | C34: Must wait for replacement drive. Reduced redundancy = risk.
B35: With reserve: | C35: Rebuild starts IMMEDIATELY. Full resiliency in minutes, not days.
B37: DRIVE SIZING ADVISORY
B38: Cost | C38: Smaller drives cheaper per TB.
B39: Rebuild Speed | C39: 3.84 TB rebuilds ~half the time of 7.68 TB.
B40: Parallelism | C40: More drives = more IOPS. 8 drives/node > 4.
B41: Reserve Cost | C41: Smaller drive = smaller reserve = more for volumes.
B42: Slots | C42: Limited NVMe slots per server. Check hardware spec.

Sheet Compute Report
B2: COMPUTE CAPACITY REPORT
B3: ="All values linked to Hardware Inputs and Workload Planner tabs. Last updated: "&TEXT(NOW(),"mm/dd/yyyy hh:mm AM/PM") -> All values linked to Hardware Inputs and Workload Planner tabs. Last updated: 04/01/2026 09:30 AM
B4: CLUSTER COMPUTE HARDWARE
B5: Cluster Nodes | C5: ='Hardware Inputs'!C8 -> 3 | D5: servers
B6: Physical CPU Cores per Node | C6: ='Hardware Inputs'!C29 -> 32 | D6: cores | F6: =IF('Hardware Inputs'!C30="Yes","Hyperthreading: ON","Hyperthreading: OFF") -> Hyperthreading: ON
B7: Logical vCPU per Node | C7: ='Hardware Inputs'!C35 -> 64 | D7: vCPU | F7: ="Physical cores × "&IF('Hardware Inputs'!C30="Yes","2 (HT)","1 (no HT)") -> Physical cores × 2 (HT)
B8: RAM per Node | C8: ='Hardware Inputs'!C31 -> 256 | D8: GB total | F8: ='Hardware Inputs'!C32&" GB reserved for host OS / S2D" -> 32 GB reserved for host OS / S2D
B9: Usable RAM per Node | C9: ='Hardware Inputs'!C36 -> 224 | D9: GB | F9: After host OS reservation.
B11: Total Cluster vCPU | C11: ='Hardware Inputs'!C37 -> 192 | D11: vCPU | F11: =C5&" nodes × "&C7&" vCPU" -> 3 nodes × 64 vCPU
B12: Total Cluster Usable RAM | C12: ='Hardware Inputs'!C38 -> 672 | D12: GB | F12: =C5&" nodes × "&C9&" GB" -> 3 nodes × 224 GB
B14: N+1 Available vCPU (1 node down) | C14: ='Hardware Inputs'!C39 -> 128 | D14: vCPU | F14: ="With 1 of "&C5&" nodes in maintenance or failed." -> With 1 of 3 nodes in maintenance or failed.
B15: N+1 Available RAM (1 node down) | C15: ='Hardware Inputs'!C40 -> 448 | D15: GB | F15: Plan workloads to survive this scenario.
B17: COMPUTE DEMAND BY SCENARIO
B18: Scenario | C18: Status | D18: vCPU | E18: RAM (GB) | F18: Overcommit | G18: Eff. vCPU
B19: S1: AVD | C19: =IF('Workload Planner'!C8="Yes","Enabled","— Disabled") -> — Disabled | D19: ='Workload Planner'!C35 -> 0 | E19: ='Workload Planner'!C36 -> 0 | F19: ='Workload Planner'!C29 -> 4:1 | G19: ='Workload Planner'!C37 -> 0
B20: S2: AKS on Azure Local | C20: =IF('Workload Planner'!C44="Yes","Enabled","— Disabled") -> — Disabled | D20: ='Workload Planner'!C62 -> 0 | E20: =IF('Workload Planner'!C44="No",0,('Workload Planner'!C47*'Workload Planner'!C58)+('Workload Planner'!C48*'Workload Planner'!C60)) -> 0 | F20: ='Workload Planner'!C61 -> 4:1 | G20: ='Workload Planner'!C63 -> 0
B21: S3: Infrastructure VMs | C21: =IF('Workload Planner'!C66="Yes","Enabled","— Disabled") -> — Disabled | D21: ='Workload Planner'!C76 -> 0 | E21: =IF('Workload Planner'!C66="No",0,'Workload Planner'!C67*'Workload Planner'!C74) -> 0 | F21: ='Workload Planner'!C75 -> 4:1 | G21: ='Workload Planner'!C77 -> 0
B22: S4: Dev/Test VMs | C22: =IF('Workload Planner'!C83="Yes","Enabled","— Disabled") -> — Disabled | D22: ='Workload Planner'!C93 -> 0 | E22: =IF('Workload Planner'!C83="No",0,'Workload Planner'!C84*'Workload Planner'!C91) -> 0 | F22: ='Workload Planner'!C92 -> 4:1 | G22: ='Workload Planner'!C94 -> 0
B23: SOFS VMs | C23: Enabled | D23: ='SOFS Planner'!C46 -> 0 | E23: ='SOFS Planner'!C47 -> 0 | F23: 0.042361111 | G23: =D23 -> 0
B24: TOTALS | D24: =SUM(D19:D23) -> 0 | E24: =SUM(E19:E23) -> 0 | G24: =SUM(G19:G23) -> 0
B26: CAPACITY RESULT
B27: REMAINING vCPU | C27: =C11-G24 -> 192 | D27: vCPU | F27: =IF(C27<0,"OVER CAPACITY!",IF(G24/C11>0.7,"Caution: Above 70% utilization.","Healthy.")) -> Healthy.
B28: vCPU Utilization | C28: =IF(C11=0,0,G24/C11) -> 0 | F28: =G24&" of "&C11&" vCPU consumed (after overcommit)" -> 0 of 192 vCPU consumed (after overcommit)
B30: REMAINING RAM | C30: =C12-E24 -> 672 | D30: GB | F30: =IF(C30<0,"OVER CAPACITY!",IF(E24/C12>0.7,"Caution: Above 70% utilization.","Healthy.")) -> Healthy.
B31: RAM Utilization | C31: =IF(C12=0,0,E24/C12) -> 0 | F31: =E24&" of "&C12&" GB RAM consumed" -> 0 of 672 GB RAM consumed
B33: N+1 FAILOVER ANALYSIS (1 node in maintenance)
B34: Check | C34: Demand | D34: Available | E34: Utilization | F34: Status | G34: Headroom
B35: vCPU (all nodes) | C35: =G24 -> 0 | D35: =C11 -> 192 | E35: =IF(D35=0,0,C35/D35) -> 0 | F35: =IF(C35<=D35,"✓ PASS","✗ FAIL") -> ✓ PASS | G35: =D35-C35 -> 192
B36: RAM (all nodes) | C36: =E24 -> 0 | D36: =C12 -> 672 | E36: =IF(D36=0,0,C36/D36) -> 0 | F36: =IF(C36<=D36,"✓ PASS","✗ FAIL") -> ✓ PASS | G36: =D36-C36 -> 672
B37: N+1 vCPU (1 node down) | C37: =G24 -> 0 | D37: =C14 -> 128 | E37: =IF(D37=0,0,C37/D37) -> 0 | F37: =IF(C37<=D37,"✓ PASS","⚠ WARNING") -> ✓ PASS | G37: =D37-C37 -> 128
B38: N+1 RAM (1 node down) | C38: =E24 -> 0 | D38: =C15 -> 448 | E38: =IF(D38=0,0,C38/D38) -> 0 | F38: =IF(C38<=D38,"✓ PASS","⚠ WARNING") -> ✓ PASS | G38: =D38-C38 -> 448
B40: AVD SESSION HOST DETAIL
B41: VM spec: vCPU per host | C41: ='Workload Planner'!C27 -> 8 | D41: vCPU
B42: VM spec: RAM per host | C42: ='Workload Planner'!C28 -> 32 | D42: GB
B43: User allocation: vCPU per user | C43: ='Workload Planner'!C30 -> 2 | D43: vCPU | F43: =IF('Workload Planner'!C30<=1,"Light user",IF('Workload Planner'!C30<=2,"Medium user","Power user")) -> Medium user
B44: User allocation: RAM per user | C44: ='Workload Planner'!C31 -> 4 | D44: GB
B45: Users per session host (max) | C45: ='Workload Planner'!C32 -> 0 | D45: users/host | F45: =IF('Workload Planner'!C8="No","","Bottleneck: "&IF(INT('Workload Planner'!C27/'Workload Planner'!C30)<INT('Workload Planner'!C28/'Workload Planner'!C31),"vCPU",IF(INT('Workload Planner'!C27/'Workload Planner'!C30)>INT('Workload Planner'!C28/'Workload Planner'!C31),"RAM","Both equal")))
B47: Concurrent users to support | C47: ='Workload Planner'!C19 -> 300 | D47: users
B48: Session hosts NEEDED | C48: ='Workload Planner'!C33 -> 0 | D48: VMs | F48: ="⌈ "&'Workload Planner'!C19&" users ÷ "&'Workload Planner'!C32&" users/host ⌉" -> ⌈ 300 users ÷ 0 users/host ⌉
B49: Session hosts CONFIGURED | C49: ='Workload Planner'!C10 -> 32 | D49: VMs | F49: ='Workload Planner'!C34
...

Sheet Final Report
B2: S2D CAPACITY CALCULATOR — FINAL REPORT
B3: ="Generated from calculator inputs. All values linked to source tabs. Last updated: "&TEXT(NOW(),"mm/dd/yyyy hh:mm AM/PM") -> Generated from calculator inputs. All values linked to source tabs. Last updated: 04/01/2026 09:30 AM
B5: SECTION 1: CLUSTER HARDWARE SUMMARY
B6: Cluster Nodes | C6: ='Hardware Inputs'!C8 -> 3 | D6: nodes
B7: Drive Configuration | C7: ='Hardware Inputs'!C9 -> All-NVMe (No Cache)
B8: Capacity Drives per Node | C8: ='Hardware Inputs'!C10 -> 4 | D8: per node
B9: Drive Size (Advertised) | C9: ='Hardware Inputs'!C11 -> 3.84 | D9: TB
B10: Total Capacity Drives | C10: ='Hardware Inputs'!C16 -> 12 | D10: drives
B11: Total Raw Capacity | C11: ='Hardware Inputs'!C18 -> 46.08 | D11: TB
B12: Usable Pool (after ~8% NVMe overhead) | C12: ='Hardware Inputs'!C20 -> 42.3936 | D12: TB
B13: Reserve (drive failure repair) | C13: ='Hardware Inputs'!C21 -> 10.5984 | D13: TB
B14: Infrastructure Volume | C14: ='Hardware Inputs'!C22 -> 0.75 | D14: TB
B15: AVAILABLE CAPACITY FOR VOLUMES | C15: ='Hardware Inputs'!C24 -> 31.0452 | D15: TB | E15: ="(WAC shows: "&ROUND('Hardware Inputs'!C24*(1000/1024)^3,2)&" TiB)" -> (WAC shows: 28.91 TiB)
B17: SECTION 2: CAPACITY ALLOCATION
B18: Available Pool Capacity | C18: ='Workload Planner'!C114 -> 31.0452 | D18: TB
B19: Total Physical Footprint (all scenarios) | C19: ='Workload Planner'!C124 -> 0 | D19: TB
B20: Total Usable Volume Capacity (logical) | C20: ='Workload Planner'!C125 -> 0 | D20: TB
B21: Volume Count | C21: ='Workload Planner'!C126 -> 0 | D21: volumes
B23: REMAINING POOL CAPACITY | C23: ='Workload Planner'!C128 -> 31.0452 | D23: TB
B24: Pool Utilization | C24: ='Workload Planner'!C129 -> 0
B25: Fit Check | C25: =IF('Workload Planner'!C128<0,"FAIL — OVER CAPACITY",IF('Workload Planner'!C129>0.7,"WARNING — Above 70% utilization","PASS — Healthy headroom")) -> PASS — Healthy headroom
C26: Used | D26: Remaining
B27: Pool Capacity | C27: ='Workload Planner'!C124 -> 0 | D27: =IF('Workload Planner'!C128>0,'Workload Planner'!C128,0) -> 31.0452
B41: SECTION 3: SCENARIO BREAKDOWN
B42: Scenario | C42: Status | D42: Resiliency | E42: Logical (TB) | F42: Efficiency | G42: Footprint (TB)
B43: S1: AVD Session Hosts | C43: =IF('Workload Planner'!C14>0,"Enabled","— Disabled") -> — Disabled | D43: ='Workload Planner'!C13 -> Two-Way Mirror | E43: =IF(C43="— Disabled","—",'Workload Planner'!C14) -> — | F43: ='Workload Planner'!D13 -> 50% eff. | G43: =IF(C43="— Disabled","—",'Workload Planner'!C15) -> —
B44: S1: AVD FSLogix Profiles | C44: =IF('Workload Planner'!C23>0,"Enabled","— Disabled") -> — Disabled | D44: ='Workload Planner'!C22 -> Three-Way Mirror | E44: =IF(C44="— Disabled","—",'Workload Planner'!C23) -> — | F44: ='Workload Planner'!D22 -> 33% eff. | G44: =IF(C44="— Disabled","—",'Workload Planner'!C24) -> —
B45: S2: AKS on Azure Local | C45: =IF('Workload Planner'!C54>0,"Enabled","— Disabled") -> — Disabled | D45: ='Workload Planner'!C53 -> Three-Way Mirror | E45: =IF(C45="— Disabled","—",'Workload Planner'!C54) -> — | F45: ='Workload Planner'!D53 -> 33% eff. | G45: =IF(C45="— Disabled","—",'Workload Planner'!C55) -> —
B46: S3: Infrastructure VMs | C46: =IF('Workload Planner'!C70>0,"Enabled","— Disabled") -> — Disabled | D46: ='Workload Planner'!C69 -> Three-Way Mirror | E46: =IF(C46="— Disabled","—",'Workload Planner'!C70) -> — | F46: ='Workload Planner'!D69 -> 33% eff. | G46: =IF(C46="— Disabled","—",'Workload Planner'!C71) -> —
B47: S4: Dev/Test VMs | C47: =IF('Workload Planner'!C87>0,"Enabled","— Disabled") -> — Disabled | D47: ='Workload Planner'!C86 -> Two-Way Mirror | E47: =IF(C47="— Disabled","—",'Workload Planner'!C87) -> — | F47: ='Workload Planner'!D86 -> 50% eff. | G47: =IF(C47="— Disabled","—",'Workload Planner'!C88) -> —
B48: S5: Backup / Archive | C48: =IF('Workload Planner'!C102>0,"Enabled","— Disabled") -> — Disabled | D48: ='Workload Planner'!C101 -> Dual Parity | E48: =IF(C48="— Disabled","—",'Workload Planner'!C102) -> — | F48: ='Workload Planner'!D101 -> 50% eff. | G48: =IF(C48="— Disabled","—",'Workload Planner'!C103) -> —
B49: S6: Custom | C49: =IF('Workload Planner'!C109>0,"Enabled","— Disabled") -> — Disabled | D49: ='Workload Planner'!C108 -> Three-Way Mirror | E49: =IF(C49="— Disabled","—",'Workload Planner'!C109) -> — | F49: ='Workload Planner'!D108 -> 33% eff. | G49: =IF(C49="— Disabled","—",'Workload Planner'!C110) -> —
B50: SOFS VM Volumes | C50: =IF('SOFS Planner'!$C$6="No","— Disabled",IF('SOFS Planner'!C9>=1,"Enabled","— Disabled")) -> — Disabled | D50: ='SOFS Planner'!C16 -> Two-Way Mirror | E50: =IF(C50="— Disabled","—",SUM('Volume Detail'!D13:'Volume Detail'!D16)) -> — | F50: =IF(C50="— Disabled","",IF('SOFS Planner'!C16="Two-Way Mirror","50% eff.",IF('SOFS Planner'!C16="Three-Way Mirror","33% eff.","varies"))) | G50: =IF(C50="— Disabled","—",'Workload Planner'!C123) -> —
B51: TOTALS | E51: ='Workload Planner'!C125 -> 0 | G51: ='Workload Planner'!C124 -> 0
B52: SCENARIO INPUT DETAILS (enabled scenarios only)
B53: AVD Session Hosts | E53: =IF('Workload Planner'!C8="No","(Disabled)","") -> (Disabled)
B54: Session host VMs | C54: ='Workload Planner'!C10 -> 32 | D54: VMs
B55: OS disk per host | C55: ='Workload Planner'!C11 -> 127 | D55: GB
B56: Data/temp disk per host | C56: ='Workload Planner'!C12 -> 50 | D56: GB
B57: Resiliency | C57: ='Workload Planner'!C13 -> Two-Way Mirror
...

Sheet Drive Layout Comparison
B2: DRIVE LAYOUT COMPARISON
B3: Same total raw capacity — different drive counts. See how reserve and available capacity change.
B5: YOUR CURRENT CONFIGURATION
B6: Cluster Nodes | C6: ='Hardware Inputs'!C8 -> 3 | D6: nodes
B7: Capacity Drives per Node | C7: ='Hardware Inputs'!C10 -> 4 | D7: drives
B8: Drive Size (Advertised) | C8: ='Hardware Inputs'!C11 -> 3.84 | D8: TB
B9: Total Raw Capacity | C9: ='Hardware Inputs'!C18 -> 46.08 | D9: TB | E9: This stays constant across all alternatives.
B10: Capacity Efficiency Factor | C10: ='Advanced Settings'!C8 -> 0.92 | E10: From Advanced Settings tab.
B12: ALTERNATIVE DRIVE LAYOUTS
B13: Drives per Node | C13: Drive Size (TB) | D13: Total Drives | E13: Usable per Drive (TB) | F13: Reserve (TB) | G13: Available Capacity (TB) | H13: vs Current
B14: =C7 -> 4 | C14: =C8 -> 3.84 | D14: =B14*C6 -> 12 | E14: =C14*C10 -> 3.5328 | F14: =MIN(C6,4)*E14 -> 10.5984 | G14: =(D14*E14)-(F14)-'Advanced Settings'!C14 -> 31.0452 | H14: ← Current
B15: 4 | C15: =ROUND($C$9/(B15*$C$6),2) -> 3.84 | D15: =B15*$C$6 -> 12 | E15: =C15*$C$10 -> 3.5328 | F15: =MIN($C$6,4)*E15 -> 10.5984 | G15: =(D15*E15)-(F15)-'Advanced Settings'!$C$14 -> 31.0452 | H15: =G15-$G$14 -> 0
B16: 5 | C16: =ROUND($C$9/(B16*$C$6),2) -> 3.07 | D16: =B16*$C$6 -> 15 | E16: =C16*$C$10 -> 2.8244 | F16: =MIN($C$6,4)*E16 -> 8.4732 | G16: =(D16*E16)-(F16)-'Advanced Settings'!$C$14 -> 33.1428 | H16: =G16-$G$14 -> 2.0976
B17: 6 | C17: =ROUND($C$9/(B17*$C$6),2) -> 2.56 | D17: =B17*$C$6 -> 18 | E17: =C17*$C$10 -> 2.3552 | F17: =MIN($C$6,4)*E17 -> 7.0656 | G17: =(D17*E17)-(F17)-'Advanced Settings'!$C$14 -> 34.578 | H17: =G17-$G$14 -> 3.5328
B18: 7 | C18: =ROUND($C$9/(B18*$C$6),2) -> 2.19 | D18: =B18*$C$6 -> 21 | E18: =C18*$C$10 -> 2.0148 | F18: =MIN($C$6,4)*E18 -> 6.0444 | G18: =(D18*E18)-(F18)-'Advanced Settings'!$C$14 -> 35.5164 | H18: =G18-$G$14 -> 4.4712
B19: 8 | C19: =ROUND($C$9/(B19*$C$6),2) -> 1.92 | D19: =B19*$C$6 -> 24 | E19: =C19*$C$10 -> 1.7664 | F19: =MIN($C$6,4)*E19 -> 5.2992 | G19: =(D19*E19)-(F19)-'Advanced Settings'!$C$14 -> 36.3444 | H19: =G19-$G$14 -> 5.2992
B20: 9 | C20: =ROUND($C$9/(B20*$C$6),2) -> 1.71 | D20: =B20*$C$6 -> 27 | E20: =C20*$C$10 -> 1.5732 | F20: =MIN($C$6,4)*E20 -> 4.7196 | G20: =(D20*E20)-(F20)-'Advanced Settings'!$C$14 -> 37.0068 | H20: =G20-$G$14 -> 5.9616
B21: 10 | C21: =ROUND($C$9/(B21*$C$6),2) -> 1.54 | D21: =B21*$C$6 -> 30 | E21: =C21*$C$10 -> 1.4168 | F21: =MIN($C$6,4)*E21 -> 4.2504 | G21: =(D21*E21)-(F21)-'Advanced Settings'!$C$14 -> 37.5036 | H21: =G21-$G$14 -> 6.4584
B23: KEY INSIGHT
B24: More drives per node = smaller drive size = smaller reserve. The reserve is always 1 drive per node (max 4), so smaller drives mean less capacity "locked up" for repair. The trade-off: more drives cost more and use more slots.
B25: Note: All alternatives maintain the same total raw capacity. Drive sizes shown are calculated (raw ÷ total drives) — actual drives must be purchased in available sizes (e.g., 1.6, 3.2, 3.84, 7.68 TB).

Sheet Thin Provisioning
B2: THIN PROVISIONING — RISKS & GUIDANCE
B4: DEFAULT: USE FIXED (THICK)
B5: Fixed allocates full footprint at creation. Guarantees capacity. STRONGLY recommended for production.
B7: WHEN THIN IS ACCEPTABLE
B8: Dev/Test | C8: Outages tolerable.
B9: FSLogix | C9: Slow growth. Monitor.
B10: Archive | C10: Infrequent access.
B11: Prototyping | C11: Right-size later.
B13: RISKS
B14: Pool Exhaustion | C14: Pool full = volumes OFFLINE = VMs crash. HARD STOP.
B15: Silent Overcommit | C15: Logical can exceed physical. No hard block.
B16: Growth Spikes | C16: Updates, snapshots consume GBs with no warning.
B17: No Reclaim | C17: Stretched clusters: TRIM disabled. Volumes only grow.
B18: Double-Thin | C18: Thin S2D + thin VHDX = two overcommit layers.
B19: Rebuild Blocked | C19: No pool space = rebuild fails = data at risk.
B21: MONITORING
B22: WAC Alerts | C22: Set threshold to 60% for thin pools.
B23: PS: Pool | C23: Get-StoragePool S2D* | Select Size, AllocatedSize
B24: PS: Volumes | C24: Get-VirtualDisk | Select Size, FootprintOnPool
B25: Azure Monitor | C25: Log Analytics for pool free space trending.
B26: Commit Ratio | C26: Logical/Physical. Alert 0.8, escalate 1.0.
B28: CHECKLIST
B29: 1. | C29: Never double-thin (S2D + VHDX).
B30: 2. | C30: WAC alert at 60% for thin.
B31: 3. | C31: Pool below 70% always.
B32: 4. | C32: Weekly: Get-StoragePool reports.
B33: 5. | C33: Azure Monitor for alerting.
B34: 6. | C34: Capacity response plan documented.
B35: 7. | C35: Quarterly: simulate drive failure.
B36: 8. | C36: Production = FIXED. Thin = dev/test only.
B37: 9. | C37: Commit ratio: alert 0.8, escalate 1.0.

Sheet References
B2: MICROSOFT REFERENCES
B3: Topic | C3: URL
B4: Plan Volumes | C4: https://learn.microsoft.com/en-us/windows-server/storage/storage-spaces/plan-volumes
B5: Fault Tolerance | C5: https://learn.microsoft.com/en-us/windows-server/storage/storage-spaces/fault-tolerance
B6: S2D Overview | C6: https://learn.microsoft.com/en-us/windows-server/storage/storage-spaces/storage-spaces-direct-overview
B7: Hardware Reqs | C7: https://learn.microsoft.com/en-us/windows-server/storage/storage-spaces/storage-spaces-direct-hardware-requirements
B8: Cache | C8: https://learn.microsoft.com/en-us/windows-server/storage/storage-spaces/cache
B9: Nested Resiliency | C9: https://learn.microsoft.com/en-us/windows-server/storage/storage-spaces/nested-resiliency
B10: Thin Provisioning | C10: https://learn.microsoft.com/en-us/azure-stack/hci/manage/thin-provisioning
B11: Azure Local Baseline | C11: https://learn.microsoft.com/en-us/azure/architecture/hybrid/azure-local-baseline
B12: Azure Local Deploy | C12: https://learn.microsoft.com/en-us/azure/azure-local/deploy/deploy-via-portal
B13: Well-Architected | C13: https://learn.microsoft.com/en-us/azure/well-architected/service-guides/azure-local
B14: AVD Sizing | C14: https://learn.microsoft.com/en-us/azure/virtual-desktop/prerequisites
... B20: FSLogix Configuration | C20: https://learn.microsoft.com/en-us/fslogix/concepts-configuration-examples

Sheet Advanced Settings
B2: ADVANCED SETTINGS
B4: DRIVE CAPACITY EFFICIENCY FACTOR
B5: Manufacturers label drives in decimal TB (1 TB = 1,000,000,000,000 bytes). Windows reports in binary TiB (1 TiB = 1,099,511,627,776 bytes). A 7.68 TB drive shows as ~6.98 TiB. Plus NVMe reserves 1-3% for wear leveling. Combined: ~8% reduction.
B7: Example: 7.68 TB at 92%: | C7: =7.68*C8 -> 7.0656 | D7: TB usable | E7: What S2D pool reports per drive.
B8: Capacity Efficiency Factor | C8: 0.92 | D8: Default: 92% | E8: Only change if vendor provides specific formatted capacity.
B10: INFRASTRUCTURE VOLUME
B11: Azure Local creates an infrastructure volume during deployment (~250 GB) for system metadata. This uses the same resiliency as workload volumes, so its footprint is larger.
B13: Infrastructure Volume Logical Size | C13: 0.25 | D13: TB (~250 GB) | E13: Size of the infrastructure volume.
B14: Infrastructure Volume Footprint | C14: =ROUND(C13/IF('Hardware Inputs'!C8>=3,1/3,IF('Hardware Inputs'!C8=2,0.5,1)),2) -> 0.75 | D14: TB in pool | E14: Three-way mirror (3+ nodes) or two-way mirror (2 nodes).
B16: TB vs TiB CONVERSION TABLE
B17: Windows Admin Center, PowerShell, and Disk Management show TiB (binary). This calculator uses TB (decimal). Use this table to cross-check.
B18: 1 TB (decimal) = | C18: =ROUND(1*(1000/1024)^3,2) -> 0.93 | D18: TiB (binary) | E18: What Windows will show.
B19: 5 TB (decimal) = | C19: =ROUND(5*(1000/1024)^3,2) -> 4.66 | D19: TiB (binary) | E19: What Windows will show.
B20: 10 TB (decimal) = | C20: =ROUND(10*(1000/1024)^3,2) -> 9.31 | D20: TiB (binary) | E20: What Windows will show.
B21: 25 TB (decimal) = | C21: =ROUND(25*(1000/1024)^3,2) -> 23.28 | D21: TiB (binary) | E21: What Windows will show.
B22: 50 TB (decimal) = | C22: =ROUND(50*(1000/1024)^3,2) -> 46.57 | D22: TiB (binary) | E22: What Windows will show.
B23: 100 TB (decimal) = | C23: =ROUND(100*(1000/1024)^3,2) -> 93.13 | D23: TiB (binary) | E23: What Windows will show.
B25: CELL PROTECTION OVERRIDES
B26: ⚠️ All formula cells on input tabs are PERMANENTLY LOCKED. If you need to override a calculated value, enter it below. The override value feeds into the system in place of the formula.
B28: HOW TO USE: Enter an override value in column D. Leave blank to use the normal formula. The "Active Value" column shows what the system is currently using. | E28: ⚠️ You accept all risk when unlocking.
B30: HARDWARE INPUTS — Calculated Fields | C30: Current Value | D30: Override (leave blank = use formula) | E30: Active Value
B31: Total Capacity Drives | C31: ='Hardware Inputs'!C16 -> 12 | E31: =IF(D31<>"",D31,C31) -> 12
B32: Total Raw Capacity (TB) | C32: ='Hardware Inputs'!C18 -> 46.08 | E32: =IF(D32<>"",D32,C32) -> 46.08
B33: Total Usable Pool Before Reserve (TB) | C33: ='Hardware Inputs'!C20 -> 42.3936 | E33: =IF(D33<>"",D33,C33) -> 42.3936
B34: Reserve (TB) | C34: ='Hardware Inputs'!C21 -> 10.5984 | E34: =IF(D34<>"",D34,C34) -> 10.5984
B35: Available Capacity for Volumes (TB) | C35: ='Hardware Inputs'!C24 -> 31.0452 | E35: =IF(D35<>"",D35,C35) -> 31.0452
B36: Total Cluster vCPU (all nodes) | C36: ='Hardware Inputs'!C37 -> 192 | E36: =IF(D36<>"",D36,C36) -> 192
B37: Total Cluster Usable RAM (GB) | C37: ='Hardware Inputs'!C38 -> 672 | E37: =IF(D37<>"",D37,C37) -> 672
B38: N+1 Available vCPU | C38: ='Hardware Inputs'!C39 -> 128 | E38: =IF(D38<>"",D38,C38) -> 128
B39: N+1 Available RAM (GB) | C39: ='Hardware Inputs'!C40 -> 448 | E39: =IF(D39<>"",D39,C39) -> 448
B41: AVD PLANNING — Calculated Fields | C41: Current Value | D41: Override | E41: Active Value
B42: Session host volume logical (TB) | C42: ='AVD Planning'!C13 -> 0 | E42: =IF(D42<>"",D42,C42) -> 0
B43: Session host footprint in pool (TB) | C43: ='AVD Planning'!C14 -> 0 | E43: =IF(D43<>"",D43,C43) -> 0
B44: Profile volume logical (TB) | C44: ='AVD Planning'!C23 -> 0 | E44: =IF(D44<>"",D44,C44) -> 0
B45: Profile footprint in pool (TB) | C45: ='AVD Planning'!C24 -> 0 | E45: =IF(D45<>"",D45,C45) -> 0
B46: AVD total storage footprint (TB) | C46: ='AVD Planning'!C25 -> 0 | E46: =IF(D46<>"",D46,C46) -> 0
B47: Users per session host (max) | C47: ='AVD Planning'!C33 -> 0 | E47: =IF(D47<>"",D47,C47) -> 0
B48: Session hosts needed | C48: ='AVD Planning'!C34 -> 0 | E48: =IF(D48<>"",D48,C48) -> 0
B49: Total AVD vCPU demand | C49: ='AVD Planning'!C36 -> 0 | E49: =IF(D49<>"",D49,C49) -> 0
B50: Total AVD RAM demand (GB) | C50: ='AVD Planning'!C37 -> 0 | E50: =IF(D50<>"",D50,C50) -> 0
...

Sheet To Do
B2: TO DO — REMAINING TASKS
B4: # | C4: Task Description | D4: Status | E4: DONE | F4: Linked To / Dependencies
B5: 1
B6: 2
B7: 3
B8: 4
B9: 5
B10: 6
B11: 7
B12: 8
B13: 9
B14: 10
B15: 11
B16: 12
... B20: 16
B22: QUESTIONS & ANSWERS LOG
B24: # | C24: Question | D24: Answer
B25: 1
B26: 2
B27: 3
B28: 4
B29: 5
B30: 6
