Workbook

Sheet How to Use
B2: S2D CAPACITY CALCULATOR — HOW TO USE
B3: Azure Local / Storage Spaces Direct — Capacity Planning Tool
B5: This workbook helps you plan storage for an Azure Local cluster using Storage Spaces Direct (S2D). Enter your hardware specs and planned workloads — the calculator tells you how much usable storage you get and whether everything fits. You do NOT need to be a storage expert.
B7: QUICK START — 3 STEPS
C8: STEP 1 | D8: Go to 'Hardware Inputs'. Use the DROPDOWN MENUS to enter: node count, drive type, drives per node, and drive size. The calculator IMMEDIATELY shows your available storage in a big green number.
C9: STEP 2 | D9: Go to 'Workload Planner'. Answer questions about your workloads: How many VMs? How big? How many AVD users? The calculator figures out volume sizes FOR YOU with a running counter showing remaining capacity.
C10: STEP 3 | D10: Review 'Capacity Report' and 'Volume Detail'. Print or share these with your team or customer. The report explains all the numbers and includes key concepts if anyone asks questions.
B12: COLOR GUIDE
C13: Blue on Yellow | D13: YOUR INPUT — only cells you edit. All have dropdowns or accept numbers.
C14: Green | D14: GOOD NEWS — available capacity, passing checks. Bigger green number = better.
C15: Blue on Light Blue | D15: CALCULATED — auto-calculated values. Do not edit.
C16: Red / Pink | D16: WARNING — footprint numbers, overcommit alerts, capacity exceeded.
C17: Orange | D17: CAUTION — reserve capacity, infrastructure overhead.
C18: Gray | D18: LABELS — descriptions explaining what each row means.
B20: TABS IN THIS WORKBOOK
C21: 1. Hardware Inputs | D21: WHERE YOU START. Enter cluster hardware with dropdowns. See your available capacity instantly. Shows TB vs TiB conversion for Windows Admin Center. Includes N+1 compute reminder.
C22: 2. Workload Planner | D22: WHERE YOU PLAN VOLUMES. Questions you can answer: VM counts, disk sizes, AVD users, profile sizes. Running counter shows remaining pool as you add workloads. 64 TB volume limit checks.
C23: 3. Advanced Settings | D23: NORMALLY DON'T TOUCH. Capacity efficiency factor (92%) with explanation. Infrastructure volume size. TB-to-TiB conversion reference table.
C24: 4. Capacity Report | D24: WHAT YOU SHARE. Executive summary, capacity term glossary, reserve explanation, drive sizing advisory, N+1 compute reminder. Print this for project documentation.
C25: 5. Thin Provisioning | D25: READ IF CONSIDERING THIN. Risks, when acceptable, monitoring commands, best practices checklist.
C26: 6. Volume Detail | D26: PER-VOLUME TABLE. Name, resiliency, efficiency, logical size, footprint, usable capacity. PASS/FAIL check.
C27: 7. Microsoft References | D27: DOCUMENTATION LINKS. 10 Microsoft Learn pages covering all S2D topics.
B29: COMMON QUESTIONS
C30: Why does Windows show different numbers? | D30: Calculator uses TB (decimal). Windows uses TiB (binary). 1 TB = 0.909 TiB. Both are correct. Row 26 on Hardware Inputs shows TiB equivalent.
C31: Why is so much capacity 'lost'? | D31: Three-way mirror = 3 copies = 33% efficiency. This is WHY data survives 2 failures. Two-way = 50%. Dual Parity = 50-80% at 4+ nodes.
C32: Why can't I use all my pool? | D32: Three deductions: Drive overhead (~8%), Reserve (~1 drive/node for auto-repair), Infrastructure volume (~250 GB for Azure Local system).
C33: What if workloads don't fit? | D33: Options: fewer VMs, Two-Way instead of Three-Way where OK, more/smaller drives, more nodes, Dual Parity for archives.
C34: Should I use thin provisioning? | D34: Production: NO, use Fixed. Thin risks pool exhaustion = VMs crash. OK for dev/test and FSLogix with monitoring. See Thin Provisioning tab.
C35: NVMe+SSD vs All-NVMe? | D35: NVMe+SSD: NVMe becomes CACHE (not capacity). Only SSD counts. All-NVMe: all drives are capacity. Most common for new Azure Local deployments.
C36: Can I add drives/nodes later? | D36: Yes. New drives auto-join pool. Adding 3rd node unlocks three-way mirror. But sizing correctly upfront is simpler than expanding later.
C37: What does N+1 compute mean? | D37: Size VMs to fit on N-1 nodes. If 1 node goes down, all VMs must failover to remaining nodes. This is CPU/RAM, separate from storage.
B39: TIPS
B40: 1. | C40: Start with Hardware Inputs before planning workloads. Know what you have before planning what to put on it.
B41: 2. | C41: Use dropdown menus — don't type resiliency types manually. Typos break formulas.
B42: 3. | C42: Include ALL disks when estimating VM sizes (OS + data disks). Typical Windows Server = 80 GB OS + 100 GB data = 180 GB.
B43: 4. | C43: For FSLogix, start at 5 GB/user if no data. Measure after 30 days and adjust.
B44: 5. | C44: Keep pool utilization below 70%. Above 70% = limited rebuild headroom. Above 90% = danger zone.
B45: 6. | C45: Consider Dual Parity for backup/archive on 4+ node clusters: 50-80% efficiency vs 33% for three-way mirror.
B46: 7. | C46: Print the Capacity Report tab for project documentation.
B47: 8. | C47: This calculator uses TB. Windows uses TiB. Numbers WILL look different. Both are correct.

Sheet Hardware Inputs
B2: S2D CAPACITY CALCULATOR — Azure Local
B3: Cluster Hardware Configuration
B5: INSTRUCTIONS: Enter values in BLUE cells (dropdowns provided). Everything else auto-calculates.
B7: STEP 1: ENTER YOUR CLUSTER HARDWARE
B8: Number of Cluster Nodes (Servers) | C8: 3 | D8: Select 1-16 | E8: Physical servers in the Azure Local cluster.
B9: Drive Media Configuration | C9: All-NVMe (No Cache) | D9: Select type | E9: All-NVMe: all drives are capacity. NVMe+SSD: NVMe is CACHE only.
B10: Capacity Drives per Node | C10: 4 | D10: Minimum: 2 | E10: Drives per node used for CAPACITY.
B11: Size of Each Capacity Drive (TB) | C11: 7.68 | D11: e.g. 1.6, 3.2, 7.68 | E11: Vendor-advertised drive size in TB.
B12: Cache Drives per Node (NVMe+SSD only) | C12: 0 | D12: Only if NVMe+SSD | E12: NVMe cache drives per node. These do NOT add capacity.
B13: Default Volume Provisioning | C13: Fixed (Thick) | D13: Select type | E13: RECOMMENDED: Fixed. See Thin Provisioning tab for risks.
B15: STEP 2: YOUR AVAILABLE STORAGE (Auto-Calculated)
B16: Total Capacity Drives | C16: =C8*C10 -> 12 | D16: drives | E16: Nodes x Capacity Drives (excludes cache)
B17: Cache Drives (if applicable) | C17: =IF(C9="NVMe + SSD (NVMe is Cache)",C8*C12,0) -> 0 | D17: drives | E17: Cache drives do NOT count toward capacity.
B18: Total Raw Capacity (Advertised) | C18: =C16*C11 -> 92.16 | D18: TB | E18: Capacity Drives x Drive Size.
B19: Usable Capacity per Drive | C19: =C11*'Advanced Settings'!C8 -> 7.0656 | D19: TB | E19: After NVMe overhead (~8%). See Advanced Settings tab.
B20: Total Usable Pool (Before Reserve) | C20: =C16*C19 -> 84.7872 | D20: TB | E20: All capacity drives pooled after overhead.
B21: Reserve (drive failure repair) | C21: =MIN(C8,4)*C19 -> 21.1968 | D21: TB | E21: 1 drive per node (max 4) for auto-repair.
B22: Infrastructure Volume (Azure Local) | C22: ='Advanced Settings'!C14 -> 0.75 | D22: TB footprint | E22: System volume created during deployment (~250 GB).
B24: YOUR AVAILABLE CAPACITY FOR VOLUMES | C24: =C20-C21-C22 -> 62.8404 | D24: TB | E24: Pool minus reserve minus infra = what you can use.
B26: What Windows Admin Center shows (TiB): | C26: =ROUND(C24*1000/1024,2) -> 61.37 | D26: TiB (approx) | E26: Windows uses TiB (binary). 1 TB = ~0.909 TiB. Numbers WILL differ.
B28: N+1 COMPUTE REMINDER
B29: =CONCATENATE("Your ",C8,"-node cluster: size VM workloads to fit on ",C8-1," nodes. If 1 node goes down, VMs must failover. This is CPU/RAM, separate from storage.") -> Your 3-node cluster: size VM workloads to fit on 2 nodes. If 1 node goes down, VMs must failover. This is CPU/RAM, separate from storage.
B31: RESILIENCY REFERENCE
B32: Type | C32: Efficiency | D32: Min Nodes | E32: Fault Tolerance
B33: Two-Way Mirror | C33: 50.0% | D33: 2 | E33: 1 failure
B34: Three-Way Mirror | C34: 33.3% | D34: 3 | E34: 2 failures
B35: Dual Parity (4-6) | C35: 50.0% | D35: 4 | E35: 2 failures
B36: Dual Parity (7-8) | C36: 66.7% | D36: 7 | E36: 2 failures
B37: Dual Parity (9-15 flash) | C37: 75.0% | D37: 9 | E37: 2 failures
B38: Dual Parity (16 flash) | C38: 80.0% | D38: 16 | E38: 2 failures
B39: Nested Two-Way | C39: 25.0% | D39: 2 | E39: 1 server+1 drive

Sheet Workload Planner
B2: WORKLOAD-DRIVEN VOLUME PLANNER
B3: Answer questions about your workloads — we calculate volumes for you
B5: AVAILABLE POOL CAPACITY: | C5: ='Hardware Inputs'!C24 -> 62.8404 | D5: TB | E5: ='Hardware Inputs'!C24 -> 62.8404
B7: WORKLOAD 1: PRODUCTION VMs
B8: How many production VMs? | C8: 10 | D8: VMs
B9: Average total disk size per VM? | C9: 200 | D9: GB
B10: Resiliency type | C10: Three-Way Mirror | D10: =CONCATENATE(TEXT(IF(C10="Three-Way Mirror",1/3,IF(C10="Two-Way Mirror",0.5,IF(C10="Dual Parity",IF('Hardware Inputs'!C8>=16,0.8,IF('Hardware Inputs'!C8>=9,0.75,IF('Hardware Inputs'!C8>=7,2/3,0.5))),IF(C10="Nested Two-Way Mirror",0.25,1/3)))),"0%")," eff.") -> 33% eff.
B11: Volume size needed (logical) | C11: =IF(C8=0,0,ROUND(C8*C9/1024,2)) -> 1.95 | D11: TB | E11: =IF(C11>64,"WARNING: Exceeds 64 TB max volume size!","")
B12: Physical footprint in pool | C12: =IF(C11=0,0,ROUND(C11/IF(C10="Three-Way Mirror",1/3,IF(C10="Two-Way Mirror",0.5,IF(C10="Dual Parity",IF('Hardware Inputs'!C8>=16,0.8,IF('Hardware Inputs'!C8>=9,0.75,IF('Hardware Inputs'!C8>=7,2/3,0.5))),IF(C10="Nested Two-Way Mirror",0.25,1/3)))),2)) -> 5.85 | D12: TB | E12: Logical / efficiency = pool space consumed.
B14: WORKLOAD 2: DEV/TEST VMs
B15: How many dev/test VMs? | C15: 5 | D15: VMs
B16: Average total disk size per VM? | C16: 120 | D16: GB
B17: Resiliency type | C17: Two-Way Mirror | D17: =CONCATENATE(TEXT(IF(C17="Three-Way Mirror",1/3,IF(C17="Two-Way Mirror",0.5,IF(C17="Dual Parity",IF('Hardware Inputs'!C8>=16,0.8,IF('Hardware Inputs'!C8>=9,0.75,IF('Hardware Inputs'!C8>=7,2/3,0.5))),IF(C17="Nested Two-Way Mirror",0.25,1/3)))),"0%")," eff.") -> 50% eff.
B18: Volume size needed (logical) | C18: =IF(C15=0,0,ROUND(C15*C16/1024,2)) -> 0.59 | D18: TB | E18: =IF(C18>64,"WARNING: Exceeds 64 TB max volume size!","")
B19: Physical footprint in pool | C19: =IF(C18=0,0,ROUND(C18/IF(C17="Three-Way Mirror",1/3,IF(C17="Two-Way Mirror",0.5,IF(C17="Dual Parity",IF('Hardware Inputs'!C8>=16,0.8,IF('Hardware Inputs'!C8>=9,0.75,IF('Hardware Inputs'!C8>=7,2/3,0.5))),IF(C17="Nested Two-Way Mirror",0.25,1/3)))),2)) -> 1.18 | D19: TB | E19: Logical / efficiency = pool space consumed.
B21: WORKLOAD 3: FSLogix PROFILES (AVD)
B22: How many AVD users? | C22: 50 | D22: users
B23: Average profile container size? | C23: 5 | D23: GB
B24: Growth buffer (%)? | C24: 0.3 | D24: overhead | E24: Buffer for growth. 20-50% recommended.
B25: Resiliency type | C25: Two-Way Mirror | D25: =CONCATENATE(TEXT(IF(C25="Three-Way Mirror",1/3,IF(C25="Two-Way Mirror",0.5,IF(C25="Dual Parity",IF('Hardware Inputs'!C8>=16,0.8,IF('Hardware Inputs'!C8>=9,0.75,IF('Hardware Inputs'!C8>=7,2/3,0.5))),IF(C25="Nested Two-Way Mirror",0.25,1/3)))),"0%")," eff.") -> 50% eff.
B26: Volume size needed (logical) | C26: =IF(C22=0,0,ROUND((C22*C23*(1+C24))/1024,2)) -> 0.32 | D26: TB | E26: =IF(C26>64,"WARNING: Exceeds 64 TB max volume size!","")
B27: Physical footprint in pool | C27: =IF(C26=0,0,ROUND(C26/IF(C25="Three-Way Mirror",1/3,IF(C25="Two-Way Mirror",0.5,IF(C25="Dual Parity",IF('Hardware Inputs'!C8>=16,0.8,IF('Hardware Inputs'!C8>=9,0.75,IF('Hardware Inputs'!C8>=7,2/3,0.5))),IF(C25="Nested Two-Way Mirror",0.25,1/3)))),2)) -> 0.64 | D27: TB | E27: Logical / efficiency = pool space consumed.
B28: WORKLOAD 4: BACKUP / ARCHIVE
B29: Enable this volume? | C29: Yes | E29: Set to No to skip this workload.
B30: Size needed (TB)? | C30: 3 | D30: TB
B31: Resiliency type | C31: Dual Parity | D31: =CONCATENATE(TEXT(IF(C31="Three-Way Mirror",1/3,IF(C31="Two-Way Mirror",0.5,IF(C31="Dual Parity",IF('Hardware Inputs'!C8>=16,0.8,IF('Hardware Inputs'!C8>=9,0.75,IF('Hardware Inputs'!C8>=7,2/3,0.5))),IF(C31="Nested Two-Way Mirror",0.25,1/3)))),"0%")," eff.") -> 50% eff.
B32: Volume size needed (logical) | C32: =IF(C29="No",0,C30) -> 3 | D32: TB | E32: =IF(C32>64,"WARNING: Exceeds 64 TB max volume size!","")
B33: Physical footprint in pool | C33: =IF(C32=0,0,ROUND(C32/IF(C31="Three-Way Mirror",1/3,IF(C31="Two-Way Mirror",0.5,IF(C31="Dual Parity",IF('Hardware Inputs'!C8>=16,0.8,IF('Hardware Inputs'!C8>=9,0.75,IF('Hardware Inputs'!C8>=7,2/3,0.5))),IF(C31="Nested Two-Way Mirror",0.25,1/3)))),2)) -> 6 | D33: TB | E33: Logical / efficiency = pool space consumed.
B35: WORKLOAD 5: CUSTOM (Optional)
B36: Exact volume size (TB)? | C36: 0 | D36: TB
B37: Resiliency type | C37: Three-Way Mirror | D37: =CONCATENATE(TEXT(IF(C37="Three-Way Mirror",1/3,IF(C37="Two-Way Mirror",0.5,IF(C37="Dual Parity",IF('Hardware Inputs'!C8>=16,0.8,IF('Hardware Inputs'!C8>=9,0.75,IF('Hardware Inputs'!C8>=7,2/3,0.5))),IF(C37="Nested Two-Way Mirror",0.25,1/3)))),"0%")," eff.") -> 33% eff.
B38: Volume size needed (logical) | C38: =C36 -> 0 | D38: TB | E38: =IF(C38>64,"WARNING: Exceeds 64 TB max volume size!","")
B39: Physical footprint in pool | C39: =IF(C38=0,0,ROUND(C38/IF(C37="Three-Way Mirror",1/3,IF(C37="Two-Way Mirror",0.5,IF(C37="Dual Parity",IF('Hardware Inputs'!C8>=16,0.8,IF('Hardware Inputs'!C8>=9,0.75,IF('Hardware Inputs'!C8>=7,2/3,0.5))),IF(C37="Nested Two-Way Mirror",0.25,1/3)))),2)) -> 0 | D39: TB | E39: Logical / efficiency = pool space consumed.
B42: CAPACITY SUMMARY
B43: Available Pool Capacity | C43: ='Hardware Inputs'!C24 -> 62.8404 | D43: TB | E43: Total pool capacity for volumes.
B45: WL1: Production VMs — Footprint | C45: =C12 -> 5.85 | D45: TB
B46: WL2: Dev/Test VMs — Footprint | C46: =C19 -> 1.18 | D46: TB
B47: WL3: FSLogix Profiles — Footprint | C47: =C27 -> 0.64 | D47: TB
B48: WL4: Backup/Archive — Footprint | C48: =C33 -> 6 | D48: TB
B49: WL5: Custom — Footprint | C49: =C39 -> 0 | D49: TB
...

Sheet Advanced Settings
B2: ADVANCED SETTINGS
B4: DRIVE CAPACITY EFFICIENCY FACTOR
B5: Manufacturers label drives in decimal TB (1 TB = 1,000,000,000,000 bytes). Windows reports in binary TiB (1 TiB = 1,099,511,627,776 bytes). A 7.68 TB drive shows as ~6.98 TiB. Plus NVMe reserves 1-3% for wear leveling. Combined: ~8% reduction.
B7: Example: 7.68 TB at 92%: | C7: =7.68*C8 -> 7.0656 | D7: TB usable | E7: What S2D pool reports per drive.
B8: Capacity Efficiency Factor | C8: 0.92 | D8: Default: 92% | E8: Only change if vendor provides specific formatted capacity.
B10: INFRASTRUCTURE VOLUME
B11: Azure Local creates an infrastructure volume during deployment (~250 GB) for system metadata. This uses the same resiliency as workload volumes, so its footprint is larger.
B13: Infrastructure Volume Logical Size | C13: 0.25 | D13: TB (~250 GB) | E13: Size of the infrastructure volume.
B14: Infrastructure Volume Footprint | C14: =ROUND(C13/IF('Hardware Inputs'!C8>=3,1/3,IF('Hardware Inputs'!C8=2,0.5,1)),2) -> 0.75 | D14: TB in pool | E14: Three-way mirror (3+ nodes) or two-way mirror (2 nodes).
B16: TB vs TiB CONVERSION TABLE
B17: Windows Admin Center, PowerShell, and Disk Management show TiB (binary). This calculator uses TB (decimal). Use this table to cross-check.
B18: 1 TB (decimal) = | C18: =ROUND(1*(1000/1024)^3,2) -> 0.93 | D18: TiB (binary) | E18: What Windows will show.
B19: 5 TB (decimal) = | C19: =ROUND(5*(1000/1024)^3,2) -> 4.66 | D19: TiB (binary) | E19: What Windows will show.
B20: 10 TB (decimal) = | C20: =ROUND(10*(1000/1024)^3,2) -> 9.31 | D20: TiB (binary) | E20: What Windows will show.
B21: 25 TB (decimal) = | C21: =ROUND(25*(1000/1024)^3,2) -> 23.28 | D21: TiB (binary) | E21: What Windows will show.
B22: 50 TB (decimal) = | C22: =ROUND(50*(1000/1024)^3,2) -> 46.57 | D22: TiB (binary) | E22: What Windows will show.
B23: 100 TB (decimal) = | C23: =ROUND(100*(1000/1024)^3,2) -> 93.13 | D23: TiB (binary) | E23: What Windows will show.

Sheet Capacity Report
B2: S2D CAPACITY REPORT
B4: EXECUTIVE SUMMARY
B5: Cluster Nodes | C5: ='Hardware Inputs'!C8 -> 3 | D5: servers
B6: Drive Config | C6: ='Hardware Inputs'!C9 -> All-NVMe (No Cache)
B7: Capacity Drives | C7: ='Hardware Inputs'!C16 -> 12 | D7: drives
B8: Drive Size | C8: ='Hardware Inputs'!C11 -> 7.68 | D8: TB each
B9: Raw Capacity | C9: ='Hardware Inputs'!C18 -> 92.16 | D9: TB
B10: After Overhead | C10: ='Hardware Inputs'!C20 -> 84.7872 | D10: TB
B11: Pool Reserve | C11: ='Hardware Inputs'!C21 -> 21.1968 | D11: TB
B12: Infra Volume | C12: ='Hardware Inputs'!C22 -> 0.75 | D12: TB
B13: AVAILABLE POOL | C13: ='Hardware Inputs'!C24 -> 62.8404 | D13: TB
B14: WAC Display | C14: ='Hardware Inputs'!C26 -> 61.37 | D14: TiB
B15: Workload Footprint | C15: ='Workload Planner'!C51 -> 13.67 | D15: TB
B16: Usable Volume Capacity | C16: ='Workload Planner'!C52 -> 5.86 | D16: TB
B17: Remaining Free | C17: ='Workload Planner'!C55 -> 49.1704 | D17: TB
B18: Pool Utilization | C18: ='Workload Planner'!C56 -> 0.21753522
B20: CAPACITY TERMS
B21: Raw Capacity | C21: Drive label size. Manufacturer's decimal number.
B22: Usable Capacity | C22: After ~8% overhead (TB-to-TiB + NVMe reserves).
B23: Pool Capacity | C23: All usable capacity pooled. Excludes cache.
B24: Reserve | C24: 1 drive/node (max 4) for auto-repair.
B25: Infra Volume | C25: ~250 GB for Azure Local system metadata.
B26: Available Pool | C26: Pool - reserve - infra. What you allocate.
B27: Volume Size | C27: Logical size you request. What OS shows.
B28: Footprint | C28: Physical pool space. 1TB 3-way mirror = 3TB.
B29: Efficiency | C29: Usable/footprint. 2-way=50%, 3-way=33%.
B30: TB vs TiB | C30: Manufacturers=TB. Windows=TiB. 1TB=0.909TiB.
B32: WHY RESERVE IS CRITICAL
B33: Drive fails: | C33: S2D rebuilds lost data onto other drives. Needs FREE pool space.
B34: No reserve: | C34: Must wait for replacement drive. Reduced redundancy = risk.
B35: With reserve: | C35: Rebuild starts IMMEDIATELY. Full resiliency in minutes, not days.
B37: DRIVE SIZING ADVISORY
B38: Cost | C38: Smaller drives cheaper per TB.
B39: Rebuild Speed | C39: 3.84 TB rebuilds ~half the time of 7.68 TB.
B40: Parallelism | C40: More drives = more IOPS. 8 drives/node > 4.
B41: Reserve Cost | C41: Smaller drive = smaller reserve = more for volumes.
B42: Slots | C42: Limited NVMe slots per server. Check hardware spec.

Sheet Thin Provisioning
B2: THIN PROVISIONING — RISKS & GUIDANCE
B4: DEFAULT: USE FIXED (THICK)
B5: Fixed allocates full footprint at creation. Guarantees capacity. STRONGLY recommended for production.
B7: WHEN THIN IS ACCEPTABLE
B8: Dev/Test | C8: Outages tolerable.
B9: FSLogix | C9: Slow growth. Monitor.
B10: Archive | C10: Infrequent access.
B11: Prototyping | C11: Right-size later.
B13: RISKS
B14: Pool Exhaustion | C14: Pool full = volumes OFFLINE = VMs crash. HARD STOP.
B15: Silent Overcommit | C15: Logical can exceed physical. No hard block.
B16: Growth Spikes | C16: Updates, snapshots consume GBs with no warning.
B17: No Reclaim | C17: Stretched clusters: TRIM disabled. Volumes only grow.
B18: Double-Thin | C18: Thin S2D + thin VHDX = two overcommit layers.
B19: Rebuild Blocked | C19: No pool space = rebuild fails = data at risk.
B21: MONITORING
B22: WAC Alerts | C22: Set threshold to 60% for thin pools.
B23: PS: Pool | C23: Get-StoragePool S2D* | Select Size, AllocatedSize
B24: PS: Volumes | C24: Get-VirtualDisk | Select Size, FootprintOnPool
B25: Azure Monitor | C25: Log Analytics for pool free space trending.
B26: Commit Ratio | C26: Logical/Physical. Alert 0.8, escalate 1.0.
B28: CHECKLIST
B29: 1. | C29: Never double-thin (S2D + VHDX).
B30: 2. | C30: WAC alert at 60% for thin.
B31: 3. | C31: Pool below 70% always.
B32: 4. | C32: Weekly: Get-StoragePool reports.
B33: 5. | C33: Azure Monitor for alerting.
B34: 6. | C34: Capacity response plan documented.
B35: 7. | C35: Quarterly: simulate drive failure.
B36: 8. | C36: Production = FIXED. Thin = dev/test only.
B37: 9. | C37: Commit ratio: alert 0.8, escalate 1.0.

Sheet Volume Detail
B2: VOLUME DETAIL
B4: Volume | C4: Resiliency | D4: Efficiency | E4: Logical TB | F4: Footprint TB | G4: Copies | H4: Usable TB
B5: Production VMs | C5: ='Workload Planner'!C9 -> 200 | D5: =IF('Workload Planner'!C9="Three-Way Mirror",1/3,IF('Workload Planner'!C9="Two-Way Mirror",0.5,IF('Workload Planner'!C9="Dual Parity",IF('Hardware Inputs'!C8>=16,0.8,IF('Hardware Inputs'!C8>=9,0.75,IF('Hardware Inputs'!C8>=7,2/3,0.5))),IF('Workload Planner'!C9="Nested Two-Way Mirror",0.25,1/3)))) -> 0.33333333 | E5: ='Workload Planner'!C11 -> 1.95 | F5: ='Workload Planner'!C12 -> 5.85 | G5: =IF('Workload Planner'!C9="Two-Way Mirror","2x",IF('Workload Planner'!C9="Three-Way Mirror","3x","parity")) -> parity | H5: ='Workload Planner'!C11 -> 1.95
B6: Dev/Test VMs | C6: ='Workload Planner'!C16 -> 120 | D6: =IF('Workload Planner'!C16="Three-Way Mirror",1/3,IF('Workload Planner'!C16="Two-Way Mirror",0.5,IF('Workload Planner'!C16="Dual Parity",IF('Hardware Inputs'!C8>=16,0.8,IF('Hardware Inputs'!C8>=9,0.75,IF('Hardware Inputs'!C8>=7,2/3,0.5))),IF('Workload Planner'!C16="Nested Two-Way Mirror",0.25,1/3)))) -> 0.33333333 | E6: ='Workload Planner'!C18 -> 0.59 | F6: ='Workload Planner'!C19 -> 1.18 | G6: =IF('Workload Planner'!C16="Two-Way Mirror","2x",IF('Workload Planner'!C16="Three-Way Mirror","3x","parity")) -> parity | H6: ='Workload Planner'!C18 -> 0.59
B7: FSLogix Profiles | C7: ='Workload Planner'!C24 -> 0.3 | D7: =IF('Workload Planner'!C24="Three-Way Mirror",1/3,IF('Workload Planner'!C24="Two-Way Mirror",0.5,IF('Workload Planner'!C24="Dual Parity",IF('Hardware Inputs'!C8>=16,0.8,IF('Hardware Inputs'!C8>=9,0.75,IF('Hardware Inputs'!C8>=7,2/3,0.5))),IF('Workload Planner'!C24="Nested Two-Way Mirror",0.25,1/3)))) -> 0.33333333 | E7: ='Workload Planner'!C26 -> 0.32 | F7: ='Workload Planner'!C27 -> 0.64 | G7: =IF('Workload Planner'!C24="Two-Way Mirror","2x",IF('Workload Planner'!C24="Three-Way Mirror","3x","parity")) -> parity | H7: ='Workload Planner'!C26 -> 0.32
B8: Backup/Archive | C8: ='Workload Planner'!C30 -> 3 | D8: =IF('Workload Planner'!C30="Three-Way Mirror",1/3,IF('Workload Planner'!C30="Two-Way Mirror",0.5,IF('Workload Planner'!C30="Dual Parity",IF('Hardware Inputs'!C8>=16,0.8,IF('Hardware Inputs'!C8>=9,0.75,IF('Hardware Inputs'!C8>=7,2/3,0.5))),IF('Workload Planner'!C30="Nested Two-Way Mirror",0.25,1/3)))) -> 0.33333333 | E8: ='Workload Planner'!C32 -> 3 | F8: ='Workload Planner'!C33 -> 6 | G8: =IF('Workload Planner'!C30="Two-Way Mirror","2x",IF('Workload Planner'!C30="Three-Way Mirror","3x","parity")) -> parity | H8: ='Workload Planner'!C32 -> 3
B9: Custom | C9: ='Workload Planner'!C36 -> 0 | D9: =IF('Workload Planner'!C36="Three-Way Mirror",1/3,IF('Workload Planner'!C36="Two-Way Mirror",0.5,IF('Workload Planner'!C36="Dual Parity",IF('Hardware Inputs'!C8>=16,0.8,IF('Hardware Inputs'!C8>=9,0.75,IF('Hardware Inputs'!C8>=7,2/3,0.5))),IF('Workload Planner'!C36="Nested Two-Way Mirror",0.25,1/3)))) -> 0.33333333 | E9: ='Workload Planner'!C38 -> 0 | F9: ='Workload Planner'!C39 -> 0 | G9: =IF('Workload Planner'!C36="Two-Way Mirror","2x",IF('Workload Planner'!C36="Three-Way Mirror","3x","parity")) -> parity | H9: ='Workload Planner'!C38 -> 0
B11: TOTALS | E11: =SUM(E5:E9) -> 5.86 | F11: =SUM(F5:F9) -> 13.67 | H11: =SUM(H5:H9) -> 5.86
B13: FIT CHECK
B14: =IF('Workload Planner'!C55<0,"FAIL: Exceeds pool by "&TEXT(ABS('Workload Planner'!C55),"0.00")&" TB.",IF('Workload Planner'!C56>0.7,"WARNING: Above 70%.","PASS: Healthy headroom.")) -> PASS: Healthy headroom.

Sheet References
B2: MICROSOFT REFERENCES
B3: Topic | C3: URL
B4: Plan Volumes | C4: https://learn.microsoft.com/en-us/windows-server/storage/storage-spaces/plan-volumes
B5: Fault Tolerance | C5: https://learn.microsoft.com/en-us/windows-server/storage/storage-spaces/fault-tolerance
B6: S2D Overview | C6: https://learn.microsoft.com/en-us/windows-server/storage/storage-spaces/storage-spaces-direct-overview
B7: Hardware Reqs | C7: https://learn.microsoft.com/en-us/windows-server/storage/storage-spaces/storage-spaces-direct-hardware-requirements
B8: Cache | C8: https://learn.microsoft.com/en-us/windows-server/storage/storage-spaces/cache
B9: Nested Resiliency | C9: https://learn.microsoft.com/en-us/windows-server/storage/storage-spaces/nested-resiliency
B10: Thin Provisioning | C10: https://learn.microsoft.com/en-us/azure-stack/hci/manage/thin-provisioning
B11: Azure Local Baseline | C11: https://learn.microsoft.com/en-us/azure/architecture/hybrid/azure-local-baseline
B12: Azure Local Deploy | C12: https://learn.microsoft.com/en-us/azure/azure-local/deploy/deploy-via-portal
B13: Well-Architected | C13: https://learn.microsoft.com/en-us/azure/well-architected/service-guides/azure-local
